Here is the list of inputs:
OPTIONS jobs 2
OPTIONS queues 3
OPTIONS allotments for queue  2 is   1
OPTIONS quantum length for queue  2 is  10
OPTIONS allotments for queue  1 is   1
OPTIONS quantum length for queue  1 is  10
OPTIONS allotments for queue  0 is   1
OPTIONS quantum length for queue  0 is  10
OPTIONS boost 0
OPTIONS ioTime 4
OPTIONS stayAfterIO True
OPTIONS iobump False


For each job, three defining characteristics are given:
  startTime : at what time does the job enter the system
  runTime   : the total CPU time needed by the job to finish
  ioFreq    : every ioFreq time units, the job issues an I/O
              (the I/O takes ioTime units to complete)

Job List:
  Job  0: startTime   0 - runTime 200 - ioFreq   0
  Job  1: startTime  50 - runTime 100 - ioFreq   1


Execution Trace:

[ time 0 ] JOB BEGINS by JOB 0
[ time 0 ] Run JOB 0 at PRIORITY 2 [ TICKS 9 ALLOT 1 TIME 199 (of 200) ]
[ time 1 ] Run JOB 0 at PRIORITY 2 [ TICKS 8 ALLOT 1 TIME 198 (of 200) ]
[ time 2 ] Run JOB 0 at PRIORITY 2 [ TICKS 7 ALLOT 1 TIME 197 (of 200) ]
[ time 3 ] Run JOB 0 at PRIORITY 2 [ TICKS 6 ALLOT 1 TIME 196 (of 200) ]
[ time 4 ] Run JOB 0 at PRIORITY 2 [ TICKS 5 ALLOT 1 TIME 195 (of 200) ]
[ time 5 ] Run JOB 0 at PRIORITY 2 [ TICKS 4 ALLOT 1 TIME 194 (of 200) ]
[ time 6 ] Run JOB 0 at PRIORITY 2 [ TICKS 3 ALLOT 1 TIME 193 (of 200) ]
[ time 7 ] Run JOB 0 at PRIORITY 2 [ TICKS 2 ALLOT 1 TIME 192 (of 200) ]
[ time 8 ] Run JOB 0 at PRIORITY 2 [ TICKS 1 ALLOT 1 TIME 191 (of 200) ]
[ time 9 ] Run JOB 0 at PRIORITY 2 [ TICKS 0 ALLOT 1 TIME 190 (of 200) ]
[ time 10 ] Run JOB 0 at PRIORITY 1 [ TICKS 9 ALLOT 1 TIME 189 (of 200) ]
[ time 11 ] Run JOB 0 at PRIORITY 1 [ TICKS 8 ALLOT 1 TIME 188 (of 200) ]
[ time 12 ] Run JOB 0 at PRIORITY 1 [ TICKS 7 ALLOT 1 TIME 187 (of 200) ]
[ time 13 ] Run JOB 0 at PRIORITY 1 [ TICKS 6 ALLOT 1 TIME 186 (of 200) ]
[ time 14 ] Run JOB 0 at PRIORITY 1 [ TICKS 5 ALLOT 1 TIME 185 (of 200) ]
[ time 15 ] Run JOB 0 at PRIORITY 1 [ TICKS 4 ALLOT 1 TIME 184 (of 200) ]
[ time 16 ] Run JOB 0 at PRIORITY 1 [ TICKS 3 ALLOT 1 TIME 183 (of 200) ]
[ time 17 ] Run JOB 0 at PRIORITY 1 [ TICKS 2 ALLOT 1 TIME 182 (of 200) ]
[ time 18 ] Run JOB 0 at PRIORITY 1 [ TICKS 1 ALLOT 1 TIME 181 (of 200) ]
[ time 19 ] Run JOB 0 at PRIORITY 1 [ TICKS 0 ALLOT 1 TIME 180 (of 200) ]
[ time 20 ] Run JOB 0 at PRIORITY 0 [ TICKS 9 ALLOT 1 TIME 179 (of 200) ]
[ time 21 ] Run JOB 0 at PRIORITY 0 [ TICKS 8 ALLOT 1 TIME 178 (of 200) ]
[ time 22 ] Run JOB 0 at PRIORITY 0 [ TICKS 7 ALLOT 1 TIME 177 (of 200) ]
[ time 23 ] Run JOB 0 at PRIORITY 0 [ TICKS 6 ALLOT 1 TIME 176 (of 200) ]
[ time 24 ] Run JOB 0 at PRIORITY 0 [ TICKS 5 ALLOT 1 TIME 175 (of 200) ]
[ time 25 ] Run JOB 0 at PRIORITY 0 [ TICKS 4 ALLOT 1 TIME 174 (of 200) ]
[ time 26 ] Run JOB 0 at PRIORITY 0 [ TICKS 3 ALLOT 1 TIME 173 (of 200) ]
[ time 27 ] Run JOB 0 at PRIORITY 0 [ TICKS 2 ALLOT 1 TIME 172 (of 200) ]
[ time 28 ] Run JOB 0 at PRIORITY 0 [ TICKS 1 ALLOT 1 TIME 171 (of 200) ]
[ time 29 ] Run JOB 0 at PRIORITY 0 [ TICKS 0 ALLOT 1 TIME 170 (of 200) ]
[ time 30 ] Run JOB 0 at PRIORITY 0 [ TICKS 9 ALLOT 1 TIME 169 (of 200) ]
[ time 31 ] Run JOB 0 at PRIORITY 0 [ TICKS 8 ALLOT 1 TIME 168 (of 200) ]
[ time 32 ] Run JOB 0 at PRIORITY 0 [ TICKS 7 ALLOT 1 TIME 167 (of 200) ]
[ time 33 ] Run JOB 0 at PRIORITY 0 [ TICKS 6 ALLOT 1 TIME 166 (of 200) ]
[ time 34 ] Run JOB 0 at PRIORITY 0 [ TICKS 5 ALLOT 1 TIME 165 (of 200) ]
[ time 35 ] Run JOB 0 at PRIORITY 0 [ TICKS 4 ALLOT 1 TIME 164 (of 200) ]
[ time 36 ] Run JOB 0 at PRIORITY 0 [ TICKS 3 ALLOT 1 TIME 163 (of 200) ]
[ time 37 ] Run JOB 0 at PRIORITY 0 [ TICKS 2 ALLOT 1 TIME 162 (of 200) ]
[ time 38 ] Run JOB 0 at PRIORITY 0 [ TICKS 1 ALLOT 1 TIME 161 (of 200) ]
[ time 39 ] Run JOB 0 at PRIORITY 0 [ TICKS 0 ALLOT 1 TIME 160 (of 200) ]
[ time 40 ] Run JOB 0 at PRIORITY 0 [ TICKS 9 ALLOT 1 TIME 159 (of 200) ]
[ time 41 ] Run JOB 0 at PRIORITY 0 [ TICKS 8 ALLOT 1 TIME 158 (of 200) ]
[ time 42 ] Run JOB 0 at PRIORITY 0 [ TICKS 7 ALLOT 1 TIME 157 (of 200) ]
[ time 43 ] Run JOB 0 at PRIORITY 0 [ TICKS 6 ALLOT 1 TIME 156 (of 200) ]
[ time 44 ] Run JOB 0 at PRIORITY 0 [ TICKS 5 ALLOT 1 TIME 155 (of 200) ]
[ time 45 ] Run JOB 0 at PRIORITY 0 [ TICKS 4 ALLOT 1 TIME 154 (of 200) ]
[ time 46 ] Run JOB 0 at PRIORITY 0 [ TICKS 3 ALLOT 1 TIME 153 (of 200) ]
[ time 47 ] Run JOB 0 at PRIORITY 0 [ TICKS 2 ALLOT 1 TIME 152 (of 200) ]
[ time 48 ] Run JOB 0 at PRIORITY 0 [ TICKS 1 ALLOT 1 TIME 151 (of 200) ]
[ time 49 ] Run JOB 0 at PRIORITY 0 [ TICKS 0 ALLOT 1 TIME 150 (of 200) ]
[ time 50 ] JOB BEGINS by JOB 1
[ time 50 ] Run JOB 1 at PRIORITY 2 [ TICKS 9 ALLOT 1 TIME 99 (of 100) ]
[ time 51 ] IO_START by JOB 1
IO DONE
[ time 51 ] Run JOB 0 at PRIORITY 0 [ TICKS 9 ALLOT 1 TIME 149 (of 200) ]
[ time 52 ] Run JOB 0 at PRIORITY 0 [ TICKS 8 ALLOT 1 TIME 148 (of 200) ]
[ time 53 ] Run JOB 0 at PRIORITY 0 [ TICKS 7 ALLOT 1 TIME 147 (of 200) ]
[ time 54 ] Run JOB 0 at PRIORITY 0 [ TICKS 6 ALLOT 1 TIME 146 (of 200) ]
[ time 55 ] IO_DONE by JOB 1
[ time 55 ] Run JOB 1 at PRIORITY 2 [ TICKS 9 ALLOT 1 TIME 98 (of 100) ]
[ time 56 ] IO_START by JOB 1
IO DONE
[ time 56 ] Run JOB 0 at PRIORITY 0 [ TICKS 5 ALLOT 1 TIME 145 (of 200) ]
[ time 57 ] Run JOB 0 at PRIORITY 0 [ TICKS 4 ALLOT 1 TIME 144 (of 200) ]
[ time 58 ] Run JOB 0 at PRIORITY 0 [ TICKS 3 ALLOT 1 TIME 143 (of 200) ]
[ time 59 ] Run JOB 0 at PRIORITY 0 [ TICKS 2 ALLOT 1 TIME 142 (of 200) ]
[ time 60 ] IO_DONE by JOB 1
[ time 60 ] Run JOB 1 at PRIORITY 2 [ TICKS 9 ALLOT 1 TIME 97 (of 100) ]
[ time 61 ] IO_START by JOB 1
IO DONE
[ time 61 ] Run JOB 0 at PRIORITY 0 [ TICKS 1 ALLOT 1 TIME 141 (of 200) ]
[ time 62 ] Run JOB 0 at PRIORITY 0 [ TICKS 0 ALLOT 1 TIME 140 (of 200) ]
[ time 63 ] Run JOB 0 at PRIORITY 0 [ TICKS 9 ALLOT 1 TIME 139 (of 200) ]
[ time 64 ] Run JOB 0 at PRIORITY 0 [ TICKS 8 ALLOT 1 TIME 138 (of 200) ]
[ time 65 ] IO_DONE by JOB 1
[ time 65 ] Run JOB 1 at PRIORITY 2 [ TICKS 9 ALLOT 1 TIME 96 (of 100) ]
[ time 66 ] IO_START by JOB 1
IO DONE
[ time 66 ] Run JOB 0 at PRIORITY 0 [ TICKS 7 ALLOT 1 TIME 137 (of 200) ]
[ time 67 ] Run JOB 0 at PRIORITY 0 [ TICKS 6 ALLOT 1 TIME 136 (of 200) ]
[ time 68 ] Run JOB 0 at PRIORITY 0 [ TICKS 5 ALLOT 1 TIME 135 (of 200) ]
[ time 69 ] Run JOB 0 at PRIORITY 0 [ TICKS 4 ALLOT 1 TIME 134 (of 200) ]
[ time 70 ] IO_DONE by JOB 1
[ time 70 ] Run JOB 1 at PRIORITY 2 [ TICKS 9 ALLOT 1 TIME 95 (of 100) ]
[ time 71 ] IO_START by JOB 1
IO DONE
[ time 71 ] Run JOB 0 at PRIORITY 0 [ TICKS 3 ALLOT 1 TIME 133 (of 200) ]
[ time 72 ] Run JOB 0 at PRIORITY 0 [ TICKS 2 ALLOT 1 TIME 132 (of 200) ]
[ time 73 ] Run JOB 0 at PRIORITY 0 [ TICKS 1 ALLOT 1 TIME 131 (of 200) ]
[ time 74 ] Run JOB 0 at PRIORITY 0 [ TICKS 0 ALLOT 1 TIME 130 (of 200) ]
[ time 75 ] IO_DONE by JOB 1
[ time 75 ] Run JOB 1 at PRIORITY 2 [ TICKS 9 ALLOT 1 TIME 94 (of 100) ]
[ time 76 ] IO_START by JOB 1
IO DONE
[ time 76 ] Run JOB 0 at PRIORITY 0 [ TICKS 9 ALLOT 1 TIME 129 (of 200) ]
[ time 77 ] Run JOB 0 at PRIORITY 0 [ TICKS 8 ALLOT 1 TIME 128 (of 200) ]
[ time 78 ] Run JOB 0 at PRIORITY 0 [ TICKS 7 ALLOT 1 TIME 127 (of 200) ]
[ time 79 ] Run JOB 0 at PRIORITY 0 [ TICKS 6 ALLOT 1 TIME 126 (of 200) ]
[ time 80 ] IO_DONE by JOB 1
[ time 80 ] Run JOB 1 at PRIORITY 2 [ TICKS 9 ALLOT 1 TIME 93 (of 100) ]
[ time 81 ] IO_START by JOB 1
IO DONE
[ time 81 ] Run JOB 0 at PRIORITY 0 [ TICKS 5 ALLOT 1 TIME 125 (of 200) ]
[ time 82 ] Run JOB 0 at PRIORITY 0 [ TICKS 4 ALLOT 1 TIME 124 (of 200) ]
[ time 83 ] Run JOB 0 at PRIORITY 0 [ TICKS 3 ALLOT 1 TIME 123 (of 200) ]
[ time 84 ] Run JOB 0 at PRIORITY 0 [ TICKS 2 ALLOT 1 TIME 122 (of 200) ]
[ time 85 ] IO_DONE by JOB 1
[ time 85 ] Run JOB 1 at PRIORITY 2 [ TICKS 9 ALLOT 1 TIME 92 (of 100) ]
[ time 86 ] IO_START by JOB 1
IO DONE
[ time 86 ] Run JOB 0 at PRIORITY 0 [ TICKS 1 ALLOT 1 TIME 121 (of 200) ]
[ time 87 ] Run JOB 0 at PRIORITY 0 [ TICKS 0 ALLOT 1 TIME 120 (of 200) ]
[ time 88 ] Run JOB 0 at PRIORITY 0 [ TICKS 9 ALLOT 1 TIME 119 (of 200) ]
[ time 89 ] Run JOB 0 at PRIORITY 0 [ TICKS 8 ALLOT 1 TIME 118 (of 200) ]
[ time 90 ] IO_DONE by JOB 1
[ time 90 ] Run JOB 1 at PRIORITY 2 [ TICKS 9 ALLOT 1 TIME 91 (of 100) ]
[ time 91 ] IO_START by JOB 1
IO DONE
[ time 91 ] Run JOB 0 at PRIORITY 0 [ TICKS 7 ALLOT 1 TIME 117 (of 200) ]
[ time 92 ] Run JOB 0 at PRIORITY 0 [ TICKS 6 ALLOT 1 TIME 116 (of 200) ]
[ time 93 ] Run JOB 0 at PRIORITY 0 [ TICKS 5 ALLOT 1 TIME 115 (of 200) ]
[ time 94 ] Run JOB 0 at PRIORITY 0 [ TICKS 4 ALLOT 1 TIME 114 (of 200) ]
[ time 95 ] IO_DONE by JOB 1
[ time 95 ] Run JOB 1 at PRIORITY 2 [ TICKS 9 ALLOT 1 TIME 90 (of 100) ]
[ time 96 ] IO_START by JOB 1
IO DONE
[ time 96 ] Run JOB 0 at PRIORITY 0 [ TICKS 3 ALLOT 1 TIME 113 (of 200) ]
[ time 97 ] Run JOB 0 at PRIORITY 0 [ TICKS 2 ALLOT 1 TIME 112 (of 200) ]
[ time 98 ] Run JOB 0 at PRIORITY 0 [ TICKS 1 ALLOT 1 TIME 111 (of 200) ]
[ time 99 ] Run JOB 0 at PRIORITY 0 [ TICKS 0 ALLOT 1 TIME 110 (of 200) ]
[ time 100 ] IO_DONE by JOB 1
[ time 100 ] Run JOB 1 at PRIORITY 2 [ TICKS 9 ALLOT 1 TIME 89 (of 100) ]
[ time 101 ] IO_START by JOB 1
IO DONE
[ time 101 ] Run JOB 0 at PRIORITY 0 [ TICKS 9 ALLOT 1 TIME 109 (of 200) ]
[ time 102 ] Run JOB 0 at PRIORITY 0 [ TICKS 8 ALLOT 1 TIME 108 (of 200) ]
[ time 103 ] Run JOB 0 at PRIORITY 0 [ TICKS 7 ALLOT 1 TIME 107 (of 200) ]
[ time 104 ] Run JOB 0 at PRIORITY 0 [ TICKS 6 ALLOT 1 TIME 106 (of 200) ]
[ time 105 ] IO_DONE by JOB 1
[ time 105 ] Run JOB 1 at PRIORITY 2 [ TICKS 9 ALLOT 1 TIME 88 (of 100) ]
[ time 106 ] IO_START by JOB 1
IO DONE
[ time 106 ] Run JOB 0 at PRIORITY 0 [ TICKS 5 ALLOT 1 TIME 105 (of 200) ]
[ time 107 ] Run JOB 0 at PRIORITY 0 [ TICKS 4 ALLOT 1 TIME 104 (of 200) ]
[ time 108 ] Run JOB 0 at PRIORITY 0 [ TICKS 3 ALLOT 1 TIME 103 (of 200) ]
[ time 109 ] Run JOB 0 at PRIORITY 0 [ TICKS 2 ALLOT 1 TIME 102 (of 200) ]
[ time 110 ] IO_DONE by JOB 1
[ time 110 ] Run JOB 1 at PRIORITY 2 [ TICKS 9 ALLOT 1 TIME 87 (of 100) ]
[ time 111 ] IO_START by JOB 1
IO DONE
[ time 111 ] Run JOB 0 at PRIORITY 0 [ TICKS 1 ALLOT 1 TIME 101 (of 200) ]
[ time 112 ] Run JOB 0 at PRIORITY 0 [ TICKS 0 ALLOT 1 TIME 100 (of 200) ]
[ time 113 ] Run JOB 0 at PRIORITY 0 [ TICKS 9 ALLOT 1 TIME 99 (of 200) ]
[ time 114 ] Run JOB 0 at PRIORITY 0 [ TICKS 8 ALLOT 1 TIME 98 (of 200) ]
[ time 115 ] IO_DONE by JOB 1
[ time 115 ] Run JOB 1 at PRIORITY 2 [ TICKS 9 ALLOT 1 TIME 86 (of 100) ]
[ time 116 ] IO_START by JOB 1
IO DONE
[ time 116 ] Run JOB 0 at PRIORITY 0 [ TICKS 7 ALLOT 1 TIME 97 (of 200) ]
[ time 117 ] Run JOB 0 at PRIORITY 0 [ TICKS 6 ALLOT 1 TIME 96 (of 200) ]
[ time 118 ] Run JOB 0 at PRIORITY 0 [ TICKS 5 ALLOT 1 TIME 95 (of 200) ]
[ time 119 ] Run JOB 0 at PRIORITY 0 [ TICKS 4 ALLOT 1 TIME 94 (of 200) ]
[ time 120 ] IO_DONE by JOB 1
[ time 120 ] Run JOB 1 at PRIORITY 2 [ TICKS 9 ALLOT 1 TIME 85 (of 100) ]
[ time 121 ] IO_START by JOB 1
IO DONE
[ time 121 ] Run JOB 0 at PRIORITY 0 [ TICKS 3 ALLOT 1 TIME 93 (of 200) ]
[ time 122 ] Run JOB 0 at PRIORITY 0 [ TICKS 2 ALLOT 1 TIME 92 (of 200) ]
[ time 123 ] Run JOB 0 at PRIORITY 0 [ TICKS 1 ALLOT 1 TIME 91 (of 200) ]
[ time 124 ] Run JOB 0 at PRIORITY 0 [ TICKS 0 ALLOT 1 TIME 90 (of 200) ]
[ time 125 ] IO_DONE by JOB 1
[ time 125 ] Run JOB 1 at PRIORITY 2 [ TICKS 9 ALLOT 1 TIME 84 (of 100) ]
[ time 126 ] IO_START by JOB 1
IO DONE
[ time 126 ] Run JOB 0 at PRIORITY 0 [ TICKS 9 ALLOT 1 TIME 89 (of 200) ]
[ time 127 ] Run JOB 0 at PRIORITY 0 [ TICKS 8 ALLOT 1 TIME 88 (of 200) ]
[ time 128 ] Run JOB 0 at PRIORITY 0 [ TICKS 7 ALLOT 1 TIME 87 (of 200) ]
[ time 129 ] Run JOB 0 at PRIORITY 0 [ TICKS 6 ALLOT 1 TIME 86 (of 200) ]
[ time 130 ] IO_DONE by JOB 1
[ time 130 ] Run JOB 1 at PRIORITY 2 [ TICKS 9 ALLOT 1 TIME 83 (of 100) ]
[ time 131 ] IO_START by JOB 1
IO DONE
[ time 131 ] Run JOB 0 at PRIORITY 0 [ TICKS 5 ALLOT 1 TIME 85 (of 200) ]
[ time 132 ] Run JOB 0 at PRIORITY 0 [ TICKS 4 ALLOT 1 TIME 84 (of 200) ]
[ time 133 ] Run JOB 0 at PRIORITY 0 [ TICKS 3 ALLOT 1 TIME 83 (of 200) ]
[ time 134 ] Run JOB 0 at PRIORITY 0 [ TICKS 2 ALLOT 1 TIME 82 (of 200) ]
[ time 135 ] IO_DONE by JOB 1
[ time 135 ] Run JOB 1 at PRIORITY 2 [ TICKS 9 ALLOT 1 TIME 82 (of 100) ]
[ time 136 ] IO_START by JOB 1
IO DONE
[ time 136 ] Run JOB 0 at PRIORITY 0 [ TICKS 1 ALLOT 1 TIME 81 (of 200) ]
[ time 137 ] Run JOB 0 at PRIORITY 0 [ TICKS 0 ALLOT 1 TIME 80 (of 200) ]
[ time 138 ] Run JOB 0 at PRIORITY 0 [ TICKS 9 ALLOT 1 TIME 79 (of 200) ]
[ time 139 ] Run JOB 0 at PRIORITY 0 [ TICKS 8 ALLOT 1 TIME 78 (of 200) ]
[ time 140 ] IO_DONE by JOB 1
[ time 140 ] Run JOB 1 at PRIORITY 2 [ TICKS 9 ALLOT 1 TIME 81 (of 100) ]
[ time 141 ] IO_START by JOB 1
IO DONE
[ time 141 ] Run JOB 0 at PRIORITY 0 [ TICKS 7 ALLOT 1 TIME 77 (of 200) ]
[ time 142 ] Run JOB 0 at PRIORITY 0 [ TICKS 6 ALLOT 1 TIME 76 (of 200) ]
[ time 143 ] Run JOB 0 at PRIORITY 0 [ TICKS 5 ALLOT 1 TIME 75 (of 200) ]
[ time 144 ] Run JOB 0 at PRIORITY 0 [ TICKS 4 ALLOT 1 TIME 74 (of 200) ]
[ time 145 ] IO_DONE by JOB 1
[ time 145 ] Run JOB 1 at PRIORITY 2 [ TICKS 9 ALLOT 1 TIME 80 (of 100) ]
[ time 146 ] IO_START by JOB 1
IO DONE
[ time 146 ] Run JOB 0 at PRIORITY 0 [ TICKS 3 ALLOT 1 TIME 73 (of 200) ]
[ time 147 ] Run JOB 0 at PRIORITY 0 [ TICKS 2 ALLOT 1 TIME 72 (of 200) ]
[ time 148 ] Run JOB 0 at PRIORITY 0 [ TICKS 1 ALLOT 1 TIME 71 (of 200) ]
[ time 149 ] Run JOB 0 at PRIORITY 0 [ TICKS 0 ALLOT 1 TIME 70 (of 200) ]
[ time 150 ] IO_DONE by JOB 1
[ time 150 ] Run JOB 1 at PRIORITY 2 [ TICKS 9 ALLOT 1 TIME 79 (of 100) ]
[ time 151 ] IO_START by JOB 1
IO DONE
[ time 151 ] Run JOB 0 at PRIORITY 0 [ TICKS 9 ALLOT 1 TIME 69 (of 200) ]
[ time 152 ] Run JOB 0 at PRIORITY 0 [ TICKS 8 ALLOT 1 TIME 68 (of 200) ]
[ time 153 ] Run JOB 0 at PRIORITY 0 [ TICKS 7 ALLOT 1 TIME 67 (of 200) ]
[ time 154 ] Run JOB 0 at PRIORITY 0 [ TICKS 6 ALLOT 1 TIME 66 (of 200) ]
[ time 155 ] IO_DONE by JOB 1
[ time 155 ] Run JOB 1 at PRIORITY 2 [ TICKS 9 ALLOT 1 TIME 78 (of 100) ]
[ time 156 ] IO_START by JOB 1
IO DONE
[ time 156 ] Run JOB 0 at PRIORITY 0 [ TICKS 5 ALLOT 1 TIME 65 (of 200) ]
[ time 157 ] Run JOB 0 at PRIORITY 0 [ TICKS 4 ALLOT 1 TIME 64 (of 200) ]
[ time 158 ] Run JOB 0 at PRIORITY 0 [ TICKS 3 ALLOT 1 TIME 63 (of 200) ]
[ time 159 ] Run JOB 0 at PRIORITY 0 [ TICKS 2 ALLOT 1 TIME 62 (of 200) ]
[ time 160 ] IO_DONE by JOB 1
[ time 160 ] Run JOB 1 at PRIORITY 2 [ TICKS 9 ALLOT 1 TIME 77 (of 100) ]
[ time 161 ] IO_START by JOB 1
IO DONE
[ time 161 ] Run JOB 0 at PRIORITY 0 [ TICKS 1 ALLOT 1 TIME 61 (of 200) ]
[ time 162 ] Run JOB 0 at PRIORITY 0 [ TICKS 0 ALLOT 1 TIME 60 (of 200) ]
[ time 163 ] Run JOB 0 at PRIORITY 0 [ TICKS 9 ALLOT 1 TIME 59 (of 200) ]
[ time 164 ] Run JOB 0 at PRIORITY 0 [ TICKS 8 ALLOT 1 TIME 58 (of 200) ]
[ time 165 ] IO_DONE by JOB 1
[ time 165 ] Run JOB 1 at PRIORITY 2 [ TICKS 9 ALLOT 1 TIME 76 (of 100) ]
[ time 166 ] IO_START by JOB 1
IO DONE
[ time 166 ] Run JOB 0 at PRIORITY 0 [ TICKS 7 ALLOT 1 TIME 57 (of 200) ]
[ time 167 ] Run JOB 0 at PRIORITY 0 [ TICKS 6 ALLOT 1 TIME 56 (of 200) ]
[ time 168 ] Run JOB 0 at PRIORITY 0 [ TICKS 5 ALLOT 1 TIME 55 (of 200) ]
[ time 169 ] Run JOB 0 at PRIORITY 0 [ TICKS 4 ALLOT 1 TIME 54 (of 200) ]
[ time 170 ] IO_DONE by JOB 1
[ time 170 ] Run JOB 1 at PRIORITY 2 [ TICKS 9 ALLOT 1 TIME 75 (of 100) ]
[ time 171 ] IO_START by JOB 1
IO DONE
[ time 171 ] Run JOB 0 at PRIORITY 0 [ TICKS 3 ALLOT 1 TIME 53 (of 200) ]
[ time 172 ] Run JOB 0 at PRIORITY 0 [ TICKS 2 ALLOT 1 TIME 52 (of 200) ]
[ time 173 ] Run JOB 0 at PRIORITY 0 [ TICKS 1 ALLOT 1 TIME 51 (of 200) ]
[ time 174 ] Run JOB 0 at PRIORITY 0 [ TICKS 0 ALLOT 1 TIME 50 (of 200) ]
[ time 175 ] IO_DONE by JOB 1
[ time 175 ] Run JOB 1 at PRIORITY 2 [ TICKS 9 ALLOT 1 TIME 74 (of 100) ]
[ time 176 ] IO_START by JOB 1
IO DONE
[ time 176 ] Run JOB 0 at PRIORITY 0 [ TICKS 9 ALLOT 1 TIME 49 (of 200) ]
[ time 177 ] Run JOB 0 at PRIORITY 0 [ TICKS 8 ALLOT 1 TIME 48 (of 200) ]
[ time 178 ] Run JOB 0 at PRIORITY 0 [ TICKS 7 ALLOT 1 TIME 47 (of 200) ]
[ time 179 ] Run JOB 0 at PRIORITY 0 [ TICKS 6 ALLOT 1 TIME 46 (of 200) ]
[ time 180 ] IO_DONE by JOB 1
[ time 180 ] Run JOB 1 at PRIORITY 2 [ TICKS 9 ALLOT 1 TIME 73 (of 100) ]
[ time 181 ] IO_START by JOB 1
IO DONE
[ time 181 ] Run JOB 0 at PRIORITY 0 [ TICKS 5 ALLOT 1 TIME 45 (of 200) ]
[ time 182 ] Run JOB 0 at PRIORITY 0 [ TICKS 4 ALLOT 1 TIME 44 (of 200) ]
[ time 183 ] Run JOB 0 at PRIORITY 0 [ TICKS 3 ALLOT 1 TIME 43 (of 200) ]
[ time 184 ] Run JOB 0 at PRIORITY 0 [ TICKS 2 ALLOT 1 TIME 42 (of 200) ]
[ time 185 ] IO_DONE by JOB 1
[ time 185 ] Run JOB 1 at PRIORITY 2 [ TICKS 9 ALLOT 1 TIME 72 (of 100) ]
[ time 186 ] IO_START by JOB 1
IO DONE
[ time 186 ] Run JOB 0 at PRIORITY 0 [ TICKS 1 ALLOT 1 TIME 41 (of 200) ]
[ time 187 ] Run JOB 0 at PRIORITY 0 [ TICKS 0 ALLOT 1 TIME 40 (of 200) ]
[ time 188 ] Run JOB 0 at PRIORITY 0 [ TICKS 9 ALLOT 1 TIME 39 (of 200) ]
[ time 189 ] Run JOB 0 at PRIORITY 0 [ TICKS 8 ALLOT 1 TIME 38 (of 200) ]
[ time 190 ] IO_DONE by JOB 1
[ time 190 ] Run JOB 1 at PRIORITY 2 [ TICKS 9 ALLOT 1 TIME 71 (of 100) ]
[ time 191 ] IO_START by JOB 1
IO DONE
[ time 191 ] Run JOB 0 at PRIORITY 0 [ TICKS 7 ALLOT 1 TIME 37 (of 200) ]
[ time 192 ] Run JOB 0 at PRIORITY 0 [ TICKS 6 ALLOT 1 TIME 36 (of 200) ]
[ time 193 ] Run JOB 0 at PRIORITY 0 [ TICKS 5 ALLOT 1 TIME 35 (of 200) ]
[ time 194 ] Run JOB 0 at PRIORITY 0 [ TICKS 4 ALLOT 1 TIME 34 (of 200) ]
[ time 195 ] IO_DONE by JOB 1
[ time 195 ] Run JOB 1 at PRIORITY 2 [ TICKS 9 ALLOT 1 TIME 70 (of 100) ]
[ time 196 ] IO_START by JOB 1
IO DONE
[ time 196 ] Run JOB 0 at PRIORITY 0 [ TICKS 3 ALLOT 1 TIME 33 (of 200) ]
[ time 197 ] Run JOB 0 at PRIORITY 0 [ TICKS 2 ALLOT 1 TIME 32 (of 200) ]
[ time 198 ] Run JOB 0 at PRIORITY 0 [ TICKS 1 ALLOT 1 TIME 31 (of 200) ]
[ time 199 ] Run JOB 0 at PRIORITY 0 [ TICKS 0 ALLOT 1 TIME 30 (of 200) ]
[ time 200 ] IO_DONE by JOB 1
[ time 200 ] Run JOB 1 at PRIORITY 2 [ TICKS 9 ALLOT 1 TIME 69 (of 100) ]
[ time 201 ] IO_START by JOB 1
IO DONE
[ time 201 ] Run JOB 0 at PRIORITY 0 [ TICKS 9 ALLOT 1 TIME 29 (of 200) ]
[ time 202 ] Run JOB 0 at PRIORITY 0 [ TICKS 8 ALLOT 1 TIME 28 (of 200) ]
[ time 203 ] Run JOB 0 at PRIORITY 0 [ TICKS 7 ALLOT 1 TIME 27 (of 200) ]
[ time 204 ] Run JOB 0 at PRIORITY 0 [ TICKS 6 ALLOT 1 TIME 26 (of 200) ]
[ time 205 ] IO_DONE by JOB 1
[ time 205 ] Run JOB 1 at PRIORITY 2 [ TICKS 9 ALLOT 1 TIME 68 (of 100) ]
[ time 206 ] IO_START by JOB 1
IO DONE
[ time 206 ] Run JOB 0 at PRIORITY 0 [ TICKS 5 ALLOT 1 TIME 25 (of 200) ]
[ time 207 ] Run JOB 0 at PRIORITY 0 [ TICKS 4 ALLOT 1 TIME 24 (of 200) ]
[ time 208 ] Run JOB 0 at PRIORITY 0 [ TICKS 3 ALLOT 1 TIME 23 (of 200) ]
[ time 209 ] Run JOB 0 at PRIORITY 0 [ TICKS 2 ALLOT 1 TIME 22 (of 200) ]
[ time 210 ] IO_DONE by JOB 1
[ time 210 ] Run JOB 1 at PRIORITY 2 [ TICKS 9 ALLOT 1 TIME 67 (of 100) ]
[ time 211 ] IO_START by JOB 1
IO DONE
[ time 211 ] Run JOB 0 at PRIORITY 0 [ TICKS 1 ALLOT 1 TIME 21 (of 200) ]
[ time 212 ] Run JOB 0 at PRIORITY 0 [ TICKS 0 ALLOT 1 TIME 20 (of 200) ]
[ time 213 ] Run JOB 0 at PRIORITY 0 [ TICKS 9 ALLOT 1 TIME 19 (of 200) ]
[ time 214 ] Run JOB 0 at PRIORITY 0 [ TICKS 8 ALLOT 1 TIME 18 (of 200) ]
[ time 215 ] IO_DONE by JOB 1
[ time 215 ] Run JOB 1 at PRIORITY 2 [ TICKS 9 ALLOT 1 TIME 66 (of 100) ]
[ time 216 ] IO_START by JOB 1
IO DONE
[ time 216 ] Run JOB 0 at PRIORITY 0 [ TICKS 7 ALLOT 1 TIME 17 (of 200) ]
[ time 217 ] Run JOB 0 at PRIORITY 0 [ TICKS 6 ALLOT 1 TIME 16 (of 200) ]
[ time 218 ] Run JOB 0 at PRIORITY 0 [ TICKS 5 ALLOT 1 TIME 15 (of 200) ]
[ time 219 ] Run JOB 0 at PRIORITY 0 [ TICKS 4 ALLOT 1 TIME 14 (of 200) ]
[ time 220 ] IO_DONE by JOB 1
[ time 220 ] Run JOB 1 at PRIORITY 2 [ TICKS 9 ALLOT 1 TIME 65 (of 100) ]
[ time 221 ] IO_START by JOB 1
IO DONE
[ time 221 ] Run JOB 0 at PRIORITY 0 [ TICKS 3 ALLOT 1 TIME 13 (of 200) ]
[ time 222 ] Run JOB 0 at PRIORITY 0 [ TICKS 2 ALLOT 1 TIME 12 (of 200) ]
[ time 223 ] Run JOB 0 at PRIORITY 0 [ TICKS 1 ALLOT 1 TIME 11 (of 200) ]
[ time 224 ] Run JOB 0 at PRIORITY 0 [ TICKS 0 ALLOT 1 TIME 10 (of 200) ]
[ time 225 ] IO_DONE by JOB 1
[ time 225 ] Run JOB 1 at PRIORITY 2 [ TICKS 9 ALLOT 1 TIME 64 (of 100) ]
[ time 226 ] IO_START by JOB 1
IO DONE
[ time 226 ] Run JOB 0 at PRIORITY 0 [ TICKS 9 ALLOT 1 TIME 9 (of 200) ]
[ time 227 ] Run JOB 0 at PRIORITY 0 [ TICKS 8 ALLOT 1 TIME 8 (of 200) ]
[ time 228 ] Run JOB 0 at PRIORITY 0 [ TICKS 7 ALLOT 1 TIME 7 (of 200) ]
[ time 229 ] Run JOB 0 at PRIORITY 0 [ TICKS 6 ALLOT 1 TIME 6 (of 200) ]
[ time 230 ] IO_DONE by JOB 1
[ time 230 ] Run JOB 1 at PRIORITY 2 [ TICKS 9 ALLOT 1 TIME 63 (of 100) ]
[ time 231 ] IO_START by JOB 1
IO DONE
[ time 231 ] Run JOB 0 at PRIORITY 0 [ TICKS 5 ALLOT 1 TIME 5 (of 200) ]
[ time 232 ] Run JOB 0 at PRIORITY 0 [ TICKS 4 ALLOT 1 TIME 4 (of 200) ]
[ time 233 ] Run JOB 0 at PRIORITY 0 [ TICKS 3 ALLOT 1 TIME 3 (of 200) ]
[ time 234 ] Run JOB 0 at PRIORITY 0 [ TICKS 2 ALLOT 1 TIME 2 (of 200) ]
[ time 235 ] IO_DONE by JOB 1
[ time 235 ] Run JOB 1 at PRIORITY 2 [ TICKS 9 ALLOT 1 TIME 62 (of 100) ]
[ time 236 ] IO_START by JOB 1
IO DONE
[ time 236 ] Run JOB 0 at PRIORITY 0 [ TICKS 1 ALLOT 1 TIME 1 (of 200) ]
[ time 237 ] Run JOB 0 at PRIORITY 0 [ TICKS 0 ALLOT 1 TIME 0 (of 200) ]
[ time 238 ] FINISHED JOB 0
[ time 238 ] IDLE
[ time 239 ] IDLE
[ time 240 ] IO_DONE by JOB 1
[ time 240 ] Run JOB 1 at PRIORITY 2 [ TICKS 9 ALLOT 1 TIME 61 (of 100) ]
[ time 241 ] IO_START by JOB 1
IO DONE
[ time 241 ] IDLE
[ time 242 ] IDLE
[ time 243 ] IDLE
[ time 244 ] IDLE
[ time 245 ] IO_DONE by JOB 1
[ time 245 ] Run JOB 1 at PRIORITY 2 [ TICKS 9 ALLOT 1 TIME 60 (of 100) ]
[ time 246 ] IO_START by JOB 1
IO DONE
[ time 246 ] IDLE
[ time 247 ] IDLE
[ time 248 ] IDLE
[ time 249 ] IDLE
[ time 250 ] IO_DONE by JOB 1
[ time 250 ] Run JOB 1 at PRIORITY 2 [ TICKS 9 ALLOT 1 TIME 59 (of 100) ]
[ time 251 ] IO_START by JOB 1
IO DONE
[ time 251 ] IDLE
[ time 252 ] IDLE
[ time 253 ] IDLE
[ time 254 ] IDLE
[ time 255 ] IO_DONE by JOB 1
[ time 255 ] Run JOB 1 at PRIORITY 2 [ TICKS 9 ALLOT 1 TIME 58 (of 100) ]
[ time 256 ] IO_START by JOB 1
IO DONE
[ time 256 ] IDLE
[ time 257 ] IDLE
[ time 258 ] IDLE
[ time 259 ] IDLE
[ time 260 ] IO_DONE by JOB 1
[ time 260 ] Run JOB 1 at PRIORITY 2 [ TICKS 9 ALLOT 1 TIME 57 (of 100) ]
[ time 261 ] IO_START by JOB 1
IO DONE
[ time 261 ] IDLE
[ time 262 ] IDLE
[ time 263 ] IDLE
[ time 264 ] IDLE
[ time 265 ] IO_DONE by JOB 1
[ time 265 ] Run JOB 1 at PRIORITY 2 [ TICKS 9 ALLOT 1 TIME 56 (of 100) ]
[ time 266 ] IO_START by JOB 1
IO DONE
[ time 266 ] IDLE
[ time 267 ] IDLE
[ time 268 ] IDLE
[ time 269 ] IDLE
[ time 270 ] IO_DONE by JOB 1
[ time 270 ] Run JOB 1 at PRIORITY 2 [ TICKS 9 ALLOT 1 TIME 55 (of 100) ]
[ time 271 ] IO_START by JOB 1
IO DONE
[ time 271 ] IDLE
[ time 272 ] IDLE
[ time 273 ] IDLE
[ time 274 ] IDLE
[ time 275 ] IO_DONE by JOB 1
[ time 275 ] Run JOB 1 at PRIORITY 2 [ TICKS 9 ALLOT 1 TIME 54 (of 100) ]
[ time 276 ] IO_START by JOB 1
IO DONE
[ time 276 ] IDLE
[ time 277 ] IDLE
[ time 278 ] IDLE
[ time 279 ] IDLE
[ time 280 ] IO_DONE by JOB 1
[ time 280 ] Run JOB 1 at PRIORITY 2 [ TICKS 9 ALLOT 1 TIME 53 (of 100) ]
[ time 281 ] IO_START by JOB 1
IO DONE
[ time 281 ] IDLE
[ time 282 ] IDLE
[ time 283 ] IDLE
[ time 284 ] IDLE
[ time 285 ] IO_DONE by JOB 1
[ time 285 ] Run JOB 1 at PRIORITY 2 [ TICKS 9 ALLOT 1 TIME 52 (of 100) ]
[ time 286 ] IO_START by JOB 1
IO DONE
[ time 286 ] IDLE
[ time 287 ] IDLE
[ time 288 ] IDLE
[ time 289 ] IDLE
[ time 290 ] IO_DONE by JOB 1
[ time 290 ] Run JOB 1 at PRIORITY 2 [ TICKS 9 ALLOT 1 TIME 51 (of 100) ]
[ time 291 ] IO_START by JOB 1
IO DONE
[ time 291 ] IDLE
[ time 292 ] IDLE
[ time 293 ] IDLE
[ time 294 ] IDLE
[ time 295 ] IO_DONE by JOB 1
[ time 295 ] Run JOB 1 at PRIORITY 2 [ TICKS 9 ALLOT 1 TIME 50 (of 100) ]
[ time 296 ] IO_START by JOB 1
IO DONE
[ time 296 ] IDLE
[ time 297 ] IDLE
[ time 298 ] IDLE
[ time 299 ] IDLE
[ time 300 ] IO_DONE by JOB 1
[ time 300 ] Run JOB 1 at PRIORITY 2 [ TICKS 9 ALLOT 1 TIME 49 (of 100) ]
[ time 301 ] IO_START by JOB 1
IO DONE
[ time 301 ] IDLE
[ time 302 ] IDLE
[ time 303 ] IDLE
[ time 304 ] IDLE
[ time 305 ] IO_DONE by JOB 1
[ time 305 ] Run JOB 1 at PRIORITY 2 [ TICKS 9 ALLOT 1 TIME 48 (of 100) ]
[ time 306 ] IO_START by JOB 1
IO DONE
[ time 306 ] IDLE
[ time 307 ] IDLE
[ time 308 ] IDLE
[ time 309 ] IDLE
[ time 310 ] IO_DONE by JOB 1
[ time 310 ] Run JOB 1 at PRIORITY 2 [ TICKS 9 ALLOT 1 TIME 47 (of 100) ]
[ time 311 ] IO_START by JOB 1
IO DONE
[ time 311 ] IDLE
[ time 312 ] IDLE
[ time 313 ] IDLE
[ time 314 ] IDLE
[ time 315 ] IO_DONE by JOB 1
[ time 315 ] Run JOB 1 at PRIORITY 2 [ TICKS 9 ALLOT 1 TIME 46 (of 100) ]
[ time 316 ] IO_START by JOB 1
IO DONE
[ time 316 ] IDLE
[ time 317 ] IDLE
[ time 318 ] IDLE
[ time 319 ] IDLE
[ time 320 ] IO_DONE by JOB 1
[ time 320 ] Run JOB 1 at PRIORITY 2 [ TICKS 9 ALLOT 1 TIME 45 (of 100) ]
[ time 321 ] IO_START by JOB 1
IO DONE
[ time 321 ] IDLE
[ time 322 ] IDLE
[ time 323 ] IDLE
[ time 324 ] IDLE
[ time 325 ] IO_DONE by JOB 1
[ time 325 ] Run JOB 1 at PRIORITY 2 [ TICKS 9 ALLOT 1 TIME 44 (of 100) ]
[ time 326 ] IO_START by JOB 1
IO DONE
[ time 326 ] IDLE
[ time 327 ] IDLE
[ time 328 ] IDLE
[ time 329 ] IDLE
[ time 330 ] IO_DONE by JOB 1
[ time 330 ] Run JOB 1 at PRIORITY 2 [ TICKS 9 ALLOT 1 TIME 43 (of 100) ]
[ time 331 ] IO_START by JOB 1
IO DONE
[ time 331 ] IDLE
[ time 332 ] IDLE
[ time 333 ] IDLE
[ time 334 ] IDLE
[ time 335 ] IO_DONE by JOB 1
[ time 335 ] Run JOB 1 at PRIORITY 2 [ TICKS 9 ALLOT 1 TIME 42 (of 100) ]
[ time 336 ] IO_START by JOB 1
IO DONE
[ time 336 ] IDLE
[ time 337 ] IDLE
[ time 338 ] IDLE
[ time 339 ] IDLE
[ time 340 ] IO_DONE by JOB 1
[ time 340 ] Run JOB 1 at PRIORITY 2 [ TICKS 9 ALLOT 1 TIME 41 (of 100) ]
[ time 341 ] IO_START by JOB 1
IO DONE
[ time 341 ] IDLE
[ time 342 ] IDLE
[ time 343 ] IDLE
[ time 344 ] IDLE
[ time 345 ] IO_DONE by JOB 1
[ time 345 ] Run JOB 1 at PRIORITY 2 [ TICKS 9 ALLOT 1 TIME 40 (of 100) ]
[ time 346 ] IO_START by JOB 1
IO DONE
[ time 346 ] IDLE
[ time 347 ] IDLE
[ time 348 ] IDLE
[ time 349 ] IDLE
[ time 350 ] IO_DONE by JOB 1
[ time 350 ] Run JOB 1 at PRIORITY 2 [ TICKS 9 ALLOT 1 TIME 39 (of 100) ]
[ time 351 ] IO_START by JOB 1
IO DONE
[ time 351 ] IDLE
[ time 352 ] IDLE
[ time 353 ] IDLE
[ time 354 ] IDLE
[ time 355 ] IO_DONE by JOB 1
[ time 355 ] Run JOB 1 at PRIORITY 2 [ TICKS 9 ALLOT 1 TIME 38 (of 100) ]
[ time 356 ] IO_START by JOB 1
IO DONE
[ time 356 ] IDLE
[ time 357 ] IDLE
[ time 358 ] IDLE
[ time 359 ] IDLE
[ time 360 ] IO_DONE by JOB 1
[ time 360 ] Run JOB 1 at PRIORITY 2 [ TICKS 9 ALLOT 1 TIME 37 (of 100) ]
[ time 361 ] IO_START by JOB 1
IO DONE
[ time 361 ] IDLE
[ time 362 ] IDLE
[ time 363 ] IDLE
[ time 364 ] IDLE
[ time 365 ] IO_DONE by JOB 1
[ time 365 ] Run JOB 1 at PRIORITY 2 [ TICKS 9 ALLOT 1 TIME 36 (of 100) ]
[ time 366 ] IO_START by JOB 1
IO DONE
[ time 366 ] IDLE
[ time 367 ] IDLE
[ time 368 ] IDLE
[ time 369 ] IDLE
[ time 370 ] IO_DONE by JOB 1
[ time 370 ] Run JOB 1 at PRIORITY 2 [ TICKS 9 ALLOT 1 TIME 35 (of 100) ]
[ time 371 ] IO_START by JOB 1
IO DONE
[ time 371 ] IDLE
[ time 372 ] IDLE
[ time 373 ] IDLE
[ time 374 ] IDLE
[ time 375 ] IO_DONE by JOB 1
[ time 375 ] Run JOB 1 at PRIORITY 2 [ TICKS 9 ALLOT 1 TIME 34 (of 100) ]
[ time 376 ] IO_START by JOB 1
IO DONE
[ time 376 ] IDLE
[ time 377 ] IDLE
[ time 378 ] IDLE
[ time 379 ] IDLE
[ time 380 ] IO_DONE by JOB 1
[ time 380 ] Run JOB 1 at PRIORITY 2 [ TICKS 9 ALLOT 1 TIME 33 (of 100) ]
[ time 381 ] IO_START by JOB 1
IO DONE
[ time 381 ] IDLE
[ time 382 ] IDLE
[ time 383 ] IDLE
[ time 384 ] IDLE
[ time 385 ] IO_DONE by JOB 1
[ time 385 ] Run JOB 1 at PRIORITY 2 [ TICKS 9 ALLOT 1 TIME 32 (of 100) ]
[ time 386 ] IO_START by JOB 1
IO DONE
[ time 386 ] IDLE
[ time 387 ] IDLE
[ time 388 ] IDLE
[ time 389 ] IDLE
[ time 390 ] IO_DONE by JOB 1
[ time 390 ] Run JOB 1 at PRIORITY 2 [ TICKS 9 ALLOT 1 TIME 31 (of 100) ]
[ time 391 ] IO_START by JOB 1
IO DONE
[ time 391 ] IDLE
[ time 392 ] IDLE
[ time 393 ] IDLE
[ time 394 ] IDLE
[ time 395 ] IO_DONE by JOB 1
[ time 395 ] Run JOB 1 at PRIORITY 2 [ TICKS 9 ALLOT 1 TIME 30 (of 100) ]
[ time 396 ] IO_START by JOB 1
IO DONE
[ time 396 ] IDLE
[ time 397 ] IDLE
[ time 398 ] IDLE
[ time 399 ] IDLE
[ time 400 ] IO_DONE by JOB 1
[ time 400 ] Run JOB 1 at PRIORITY 2 [ TICKS 9 ALLOT 1 TIME 29 (of 100) ]
[ time 401 ] IO_START by JOB 1
IO DONE
[ time 401 ] IDLE
[ time 402 ] IDLE
[ time 403 ] IDLE
[ time 404 ] IDLE
[ time 405 ] IO_DONE by JOB 1
[ time 405 ] Run JOB 1 at PRIORITY 2 [ TICKS 9 ALLOT 1 TIME 28 (of 100) ]
[ time 406 ] IO_START by JOB 1
IO DONE
[ time 406 ] IDLE
[ time 407 ] IDLE
[ time 408 ] IDLE
[ time 409 ] IDLE
[ time 410 ] IO_DONE by JOB 1
[ time 410 ] Run JOB 1 at PRIORITY 2 [ TICKS 9 ALLOT 1 TIME 27 (of 100) ]
[ time 411 ] IO_START by JOB 1
IO DONE
[ time 411 ] IDLE
[ time 412 ] IDLE
[ time 413 ] IDLE
[ time 414 ] IDLE
[ time 415 ] IO_DONE by JOB 1
[ time 415 ] Run JOB 1 at PRIORITY 2 [ TICKS 9 ALLOT 1 TIME 26 (of 100) ]
[ time 416 ] IO_START by JOB 1
IO DONE
[ time 416 ] IDLE
[ time 417 ] IDLE
[ time 418 ] IDLE
[ time 419 ] IDLE
[ time 420 ] IO_DONE by JOB 1
[ time 420 ] Run JOB 1 at PRIORITY 2 [ TICKS 9 ALLOT 1 TIME 25 (of 100) ]
[ time 421 ] IO_START by JOB 1
IO DONE
[ time 421 ] IDLE
[ time 422 ] IDLE
[ time 423 ] IDLE
[ time 424 ] IDLE
[ time 425 ] IO_DONE by JOB 1
[ time 425 ] Run JOB 1 at PRIORITY 2 [ TICKS 9 ALLOT 1 TIME 24 (of 100) ]
[ time 426 ] IO_START by JOB 1
IO DONE
[ time 426 ] IDLE
[ time 427 ] IDLE
[ time 428 ] IDLE
[ time 429 ] IDLE
[ time 430 ] IO_DONE by JOB 1
[ time 430 ] Run JOB 1 at PRIORITY 2 [ TICKS 9 ALLOT 1 TIME 23 (of 100) ]
[ time 431 ] IO_START by JOB 1
IO DONE
[ time 431 ] IDLE
[ time 432 ] IDLE
[ time 433 ] IDLE
[ time 434 ] IDLE
[ time 435 ] IO_DONE by JOB 1
[ time 435 ] Run JOB 1 at PRIORITY 2 [ TICKS 9 ALLOT 1 TIME 22 (of 100) ]
[ time 436 ] IO_START by JOB 1
IO DONE
[ time 436 ] IDLE
[ time 437 ] IDLE
[ time 438 ] IDLE
[ time 439 ] IDLE
[ time 440 ] IO_DONE by JOB 1
[ time 440 ] Run JOB 1 at PRIORITY 2 [ TICKS 9 ALLOT 1 TIME 21 (of 100) ]
[ time 441 ] IO_START by JOB 1
IO DONE
[ time 441 ] IDLE
[ time 442 ] IDLE
[ time 443 ] IDLE
[ time 444 ] IDLE
[ time 445 ] IO_DONE by JOB 1
[ time 445 ] Run JOB 1 at PRIORITY 2 [ TICKS 9 ALLOT 1 TIME 20 (of 100) ]
[ time 446 ] IO_START by JOB 1
IO DONE
[ time 446 ] IDLE
[ time 447 ] IDLE
[ time 448 ] IDLE
[ time 449 ] IDLE
[ time 450 ] IO_DONE by JOB 1
[ time 450 ] Run JOB 1 at PRIORITY 2 [ TICKS 9 ALLOT 1 TIME 19 (of 100) ]
[ time 451 ] IO_START by JOB 1
IO DONE
[ time 451 ] IDLE
[ time 452 ] IDLE
[ time 453 ] IDLE
[ time 454 ] IDLE
[ time 455 ] IO_DONE by JOB 1
[ time 455 ] Run JOB 1 at PRIORITY 2 [ TICKS 9 ALLOT 1 TIME 18 (of 100) ]
[ time 456 ] IO_START by JOB 1
IO DONE
[ time 456 ] IDLE
[ time 457 ] IDLE
[ time 458 ] IDLE
[ time 459 ] IDLE
[ time 460 ] IO_DONE by JOB 1
[ time 460 ] Run JOB 1 at PRIORITY 2 [ TICKS 9 ALLOT 1 TIME 17 (of 100) ]
[ time 461 ] IO_START by JOB 1
IO DONE
[ time 461 ] IDLE
[ time 462 ] IDLE
[ time 463 ] IDLE
[ time 464 ] IDLE
[ time 465 ] IO_DONE by JOB 1
[ time 465 ] Run JOB 1 at PRIORITY 2 [ TICKS 9 ALLOT 1 TIME 16 (of 100) ]
[ time 466 ] IO_START by JOB 1
IO DONE
[ time 466 ] IDLE
[ time 467 ] IDLE
[ time 468 ] IDLE
[ time 469 ] IDLE
[ time 470 ] IO_DONE by JOB 1
[ time 470 ] Run JOB 1 at PRIORITY 2 [ TICKS 9 ALLOT 1 TIME 15 (of 100) ]
[ time 471 ] IO_START by JOB 1
IO DONE
[ time 471 ] IDLE
[ time 472 ] IDLE
[ time 473 ] IDLE
[ time 474 ] IDLE
[ time 475 ] IO_DONE by JOB 1
[ time 475 ] Run JOB 1 at PRIORITY 2 [ TICKS 9 ALLOT 1 TIME 14 (of 100) ]
[ time 476 ] IO_START by JOB 1
IO DONE
[ time 476 ] IDLE
[ time 477 ] IDLE
[ time 478 ] IDLE
[ time 479 ] IDLE
[ time 480 ] IO_DONE by JOB 1
[ time 480 ] Run JOB 1 at PRIORITY 2 [ TICKS 9 ALLOT 1 TIME 13 (of 100) ]
[ time 481 ] IO_START by JOB 1
IO DONE
[ time 481 ] IDLE
[ time 482 ] IDLE
[ time 483 ] IDLE
[ time 484 ] IDLE
[ time 485 ] IO_DONE by JOB 1
[ time 485 ] Run JOB 1 at PRIORITY 2 [ TICKS 9 ALLOT 1 TIME 12 (of 100) ]
[ time 486 ] IO_START by JOB 1
IO DONE
[ time 486 ] IDLE
[ time 487 ] IDLE
[ time 488 ] IDLE
[ time 489 ] IDLE
[ time 490 ] IO_DONE by JOB 1
[ time 490 ] Run JOB 1 at PRIORITY 2 [ TICKS 9 ALLOT 1 TIME 11 (of 100) ]
[ time 491 ] IO_START by JOB 1
IO DONE
[ time 491 ] IDLE
[ time 492 ] IDLE
[ time 493 ] IDLE
[ time 494 ] IDLE
[ time 495 ] IO_DONE by JOB 1
[ time 495 ] Run JOB 1 at PRIORITY 2 [ TICKS 9 ALLOT 1 TIME 10 (of 100) ]
[ time 496 ] IO_START by JOB 1
IO DONE
[ time 496 ] IDLE
[ time 497 ] IDLE
[ time 498 ] IDLE
[ time 499 ] IDLE
[ time 500 ] IO_DONE by JOB 1
[ time 500 ] Run JOB 1 at PRIORITY 2 [ TICKS 9 ALLOT 1 TIME 9 (of 100) ]
[ time 501 ] IO_START by JOB 1
IO DONE
[ time 501 ] IDLE
[ time 502 ] IDLE
[ time 503 ] IDLE
[ time 504 ] IDLE
[ time 505 ] IO_DONE by JOB 1
[ time 505 ] Run JOB 1 at PRIORITY 2 [ TICKS 9 ALLOT 1 TIME 8 (of 100) ]
[ time 506 ] IO_START by JOB 1
IO DONE
[ time 506 ] IDLE
[ time 507 ] IDLE
[ time 508 ] IDLE
[ time 509 ] IDLE
[ time 510 ] IO_DONE by JOB 1
[ time 510 ] Run JOB 1 at PRIORITY 2 [ TICKS 9 ALLOT 1 TIME 7 (of 100) ]
[ time 511 ] IO_START by JOB 1
IO DONE
[ time 511 ] IDLE
[ time 512 ] IDLE
[ time 513 ] IDLE
[ time 514 ] IDLE
[ time 515 ] IO_DONE by JOB 1
[ time 515 ] Run JOB 1 at PRIORITY 2 [ TICKS 9 ALLOT 1 TIME 6 (of 100) ]
[ time 516 ] IO_START by JOB 1
IO DONE
[ time 516 ] IDLE
[ time 517 ] IDLE
[ time 518 ] IDLE
[ time 519 ] IDLE
[ time 520 ] IO_DONE by JOB 1
[ time 520 ] Run JOB 1 at PRIORITY 2 [ TICKS 9 ALLOT 1 TIME 5 (of 100) ]
[ time 521 ] IO_START by JOB 1
IO DONE
[ time 521 ] IDLE
[ time 522 ] IDLE
[ time 523 ] IDLE
[ time 524 ] IDLE
[ time 525 ] IO_DONE by JOB 1
[ time 525 ] Run JOB 1 at PRIORITY 2 [ TICKS 9 ALLOT 1 TIME 4 (of 100) ]
[ time 526 ] IO_START by JOB 1
IO DONE
[ time 526 ] IDLE
[ time 527 ] IDLE
[ time 528 ] IDLE
[ time 529 ] IDLE
[ time 530 ] IO_DONE by JOB 1
[ time 530 ] Run JOB 1 at PRIORITY 2 [ TICKS 9 ALLOT 1 TIME 3 (of 100) ]
[ time 531 ] IO_START by JOB 1
IO DONE
[ time 531 ] IDLE
[ time 532 ] IDLE
[ time 533 ] IDLE
[ time 534 ] IDLE
[ time 535 ] IO_DONE by JOB 1
[ time 535 ] Run JOB 1 at PRIORITY 2 [ TICKS 9 ALLOT 1 TIME 2 (of 100) ]
[ time 536 ] IO_START by JOB 1
IO DONE
[ time 536 ] IDLE
[ time 537 ] IDLE
[ time 538 ] IDLE
[ time 539 ] IDLE
[ time 540 ] IO_DONE by JOB 1
[ time 540 ] Run JOB 1 at PRIORITY 2 [ TICKS 9 ALLOT 1 TIME 1 (of 100) ]
[ time 541 ] IO_START by JOB 1
IO DONE
[ time 541 ] IDLE
[ time 542 ] IDLE
[ time 543 ] IDLE
[ time 544 ] IDLE
[ time 545 ] IO_DONE by JOB 1
[ time 545 ] Run JOB 1 at PRIORITY 2 [ TICKS 9 ALLOT 1 TIME 0 (of 100) ]
[ time 546 ] FINISHED JOB 1

Final statistics:
  Job  0: startTime   0 - response   0 - turnaround 238
  Job  1: startTime  50 - response   0 - turnaround 496

  Avg  1: startTime n/a - response 0.00 - turnaround 367.00


