Here is the list of inputs:
OPTIONS jobs 3
OPTIONS queues 3
OPTIONS allotments for queue  2 is   1
OPTIONS quantum length for queue  2 is  10
OPTIONS allotments for queue  1 is   1
OPTIONS quantum length for queue  1 is  10
OPTIONS allotments for queue  0 is   1
OPTIONS quantum length for queue  0 is  10
OPTIONS boost 50
OPTIONS ioTime 5
OPTIONS stayAfterIO True
OPTIONS iobump False


For each job, three defining characteristics are given:
  startTime : at what time does the job enter the system
  runTime   : the total CPU time needed by the job to finish
  ioFreq    : every ioFreq time units, the job issues an I/O
              (the I/O takes ioTime units to complete)

Job List:
  Job  0: startTime   0 - runTime 200 - ioFreq   0
  Job  1: startTime 100 - runTime 100 - ioFreq   5
  Job  2: startTime 100 - runTime 100 - ioFreq   5


Execution Trace:

[ time 0 ] JOB BEGINS by JOB 0
[ time 0 ] Run JOB 0 at PRIORITY 2 [ TICKS 9 ALLOT 1 TIME 199 (of 200) ]
[ time 1 ] Run JOB 0 at PRIORITY 2 [ TICKS 8 ALLOT 1 TIME 198 (of 200) ]
[ time 2 ] Run JOB 0 at PRIORITY 2 [ TICKS 7 ALLOT 1 TIME 197 (of 200) ]
[ time 3 ] Run JOB 0 at PRIORITY 2 [ TICKS 6 ALLOT 1 TIME 196 (of 200) ]
[ time 4 ] Run JOB 0 at PRIORITY 2 [ TICKS 5 ALLOT 1 TIME 195 (of 200) ]
[ time 5 ] Run JOB 0 at PRIORITY 2 [ TICKS 4 ALLOT 1 TIME 194 (of 200) ]
[ time 6 ] Run JOB 0 at PRIORITY 2 [ TICKS 3 ALLOT 1 TIME 193 (of 200) ]
[ time 7 ] Run JOB 0 at PRIORITY 2 [ TICKS 2 ALLOT 1 TIME 192 (of 200) ]
[ time 8 ] Run JOB 0 at PRIORITY 2 [ TICKS 1 ALLOT 1 TIME 191 (of 200) ]
[ time 9 ] Run JOB 0 at PRIORITY 2 [ TICKS 0 ALLOT 1 TIME 190 (of 200) ]
[ time 10 ] Run JOB 0 at PRIORITY 1 [ TICKS 9 ALLOT 1 TIME 189 (of 200) ]
[ time 11 ] Run JOB 0 at PRIORITY 1 [ TICKS 8 ALLOT 1 TIME 188 (of 200) ]
[ time 12 ] Run JOB 0 at PRIORITY 1 [ TICKS 7 ALLOT 1 TIME 187 (of 200) ]
[ time 13 ] Run JOB 0 at PRIORITY 1 [ TICKS 6 ALLOT 1 TIME 186 (of 200) ]
[ time 14 ] Run JOB 0 at PRIORITY 1 [ TICKS 5 ALLOT 1 TIME 185 (of 200) ]
[ time 15 ] Run JOB 0 at PRIORITY 1 [ TICKS 4 ALLOT 1 TIME 184 (of 200) ]
[ time 16 ] Run JOB 0 at PRIORITY 1 [ TICKS 3 ALLOT 1 TIME 183 (of 200) ]
[ time 17 ] Run JOB 0 at PRIORITY 1 [ TICKS 2 ALLOT 1 TIME 182 (of 200) ]
[ time 18 ] Run JOB 0 at PRIORITY 1 [ TICKS 1 ALLOT 1 TIME 181 (of 200) ]
[ time 19 ] Run JOB 0 at PRIORITY 1 [ TICKS 0 ALLOT 1 TIME 180 (of 200) ]
[ time 20 ] Run JOB 0 at PRIORITY 0 [ TICKS 9 ALLOT 1 TIME 179 (of 200) ]
[ time 21 ] Run JOB 0 at PRIORITY 0 [ TICKS 8 ALLOT 1 TIME 178 (of 200) ]
[ time 22 ] Run JOB 0 at PRIORITY 0 [ TICKS 7 ALLOT 1 TIME 177 (of 200) ]
[ time 23 ] Run JOB 0 at PRIORITY 0 [ TICKS 6 ALLOT 1 TIME 176 (of 200) ]
[ time 24 ] Run JOB 0 at PRIORITY 0 [ TICKS 5 ALLOT 1 TIME 175 (of 200) ]
[ time 25 ] Run JOB 0 at PRIORITY 0 [ TICKS 4 ALLOT 1 TIME 174 (of 200) ]
[ time 26 ] Run JOB 0 at PRIORITY 0 [ TICKS 3 ALLOT 1 TIME 173 (of 200) ]
[ time 27 ] Run JOB 0 at PRIORITY 0 [ TICKS 2 ALLOT 1 TIME 172 (of 200) ]
[ time 28 ] Run JOB 0 at PRIORITY 0 [ TICKS 1 ALLOT 1 TIME 171 (of 200) ]
[ time 29 ] Run JOB 0 at PRIORITY 0 [ TICKS 0 ALLOT 1 TIME 170 (of 200) ]
[ time 30 ] Run JOB 0 at PRIORITY 0 [ TICKS 9 ALLOT 1 TIME 169 (of 200) ]
[ time 31 ] Run JOB 0 at PRIORITY 0 [ TICKS 8 ALLOT 1 TIME 168 (of 200) ]
[ time 32 ] Run JOB 0 at PRIORITY 0 [ TICKS 7 ALLOT 1 TIME 167 (of 200) ]
[ time 33 ] Run JOB 0 at PRIORITY 0 [ TICKS 6 ALLOT 1 TIME 166 (of 200) ]
[ time 34 ] Run JOB 0 at PRIORITY 0 [ TICKS 5 ALLOT 1 TIME 165 (of 200) ]
[ time 35 ] Run JOB 0 at PRIORITY 0 [ TICKS 4 ALLOT 1 TIME 164 (of 200) ]
[ time 36 ] Run JOB 0 at PRIORITY 0 [ TICKS 3 ALLOT 1 TIME 163 (of 200) ]
[ time 37 ] Run JOB 0 at PRIORITY 0 [ TICKS 2 ALLOT 1 TIME 162 (of 200) ]
[ time 38 ] Run JOB 0 at PRIORITY 0 [ TICKS 1 ALLOT 1 TIME 161 (of 200) ]
[ time 39 ] Run JOB 0 at PRIORITY 0 [ TICKS 0 ALLOT 1 TIME 160 (of 200) ]
[ time 40 ] Run JOB 0 at PRIORITY 0 [ TICKS 9 ALLOT 1 TIME 159 (of 200) ]
[ time 41 ] Run JOB 0 at PRIORITY 0 [ TICKS 8 ALLOT 1 TIME 158 (of 200) ]
[ time 42 ] Run JOB 0 at PRIORITY 0 [ TICKS 7 ALLOT 1 TIME 157 (of 200) ]
[ time 43 ] Run JOB 0 at PRIORITY 0 [ TICKS 6 ALLOT 1 TIME 156 (of 200) ]
[ time 44 ] Run JOB 0 at PRIORITY 0 [ TICKS 5 ALLOT 1 TIME 155 (of 200) ]
[ time 45 ] Run JOB 0 at PRIORITY 0 [ TICKS 4 ALLOT 1 TIME 154 (of 200) ]
[ time 46 ] Run JOB 0 at PRIORITY 0 [ TICKS 3 ALLOT 1 TIME 153 (of 200) ]
[ time 47 ] Run JOB 0 at PRIORITY 0 [ TICKS 2 ALLOT 1 TIME 152 (of 200) ]
[ time 48 ] Run JOB 0 at PRIORITY 0 [ TICKS 1 ALLOT 1 TIME 151 (of 200) ]
[ time 49 ] Run JOB 0 at PRIORITY 0 [ TICKS 0 ALLOT 1 TIME 150 (of 200) ]
[ time 50 ] BOOST ( every 50 )
[ time 50 ] Run JOB 0 at PRIORITY 2 [ TICKS 9 ALLOT 1 TIME 149 (of 200) ]
[ time 51 ] Run JOB 0 at PRIORITY 2 [ TICKS 8 ALLOT 1 TIME 148 (of 200) ]
[ time 52 ] Run JOB 0 at PRIORITY 2 [ TICKS 7 ALLOT 1 TIME 147 (of 200) ]
[ time 53 ] Run JOB 0 at PRIORITY 2 [ TICKS 6 ALLOT 1 TIME 146 (of 200) ]
[ time 54 ] Run JOB 0 at PRIORITY 2 [ TICKS 5 ALLOT 1 TIME 145 (of 200) ]
[ time 55 ] Run JOB 0 at PRIORITY 2 [ TICKS 4 ALLOT 1 TIME 144 (of 200) ]
[ time 56 ] Run JOB 0 at PRIORITY 2 [ TICKS 3 ALLOT 1 TIME 143 (of 200) ]
[ time 57 ] Run JOB 0 at PRIORITY 2 [ TICKS 2 ALLOT 1 TIME 142 (of 200) ]
[ time 58 ] Run JOB 0 at PRIORITY 2 [ TICKS 1 ALLOT 1 TIME 141 (of 200) ]
[ time 59 ] Run JOB 0 at PRIORITY 2 [ TICKS 0 ALLOT 1 TIME 140 (of 200) ]
[ time 60 ] Run JOB 0 at PRIORITY 1 [ TICKS 9 ALLOT 1 TIME 139 (of 200) ]
[ time 61 ] Run JOB 0 at PRIORITY 1 [ TICKS 8 ALLOT 1 TIME 138 (of 200) ]
[ time 62 ] Run JOB 0 at PRIORITY 1 [ TICKS 7 ALLOT 1 TIME 137 (of 200) ]
[ time 63 ] Run JOB 0 at PRIORITY 1 [ TICKS 6 ALLOT 1 TIME 136 (of 200) ]
[ time 64 ] Run JOB 0 at PRIORITY 1 [ TICKS 5 ALLOT 1 TIME 135 (of 200) ]
[ time 65 ] Run JOB 0 at PRIORITY 1 [ TICKS 4 ALLOT 1 TIME 134 (of 200) ]
[ time 66 ] Run JOB 0 at PRIORITY 1 [ TICKS 3 ALLOT 1 TIME 133 (of 200) ]
[ time 67 ] Run JOB 0 at PRIORITY 1 [ TICKS 2 ALLOT 1 TIME 132 (of 200) ]
[ time 68 ] Run JOB 0 at PRIORITY 1 [ TICKS 1 ALLOT 1 TIME 131 (of 200) ]
[ time 69 ] Run JOB 0 at PRIORITY 1 [ TICKS 0 ALLOT 1 TIME 130 (of 200) ]
[ time 70 ] Run JOB 0 at PRIORITY 0 [ TICKS 9 ALLOT 1 TIME 129 (of 200) ]
[ time 71 ] Run JOB 0 at PRIORITY 0 [ TICKS 8 ALLOT 1 TIME 128 (of 200) ]
[ time 72 ] Run JOB 0 at PRIORITY 0 [ TICKS 7 ALLOT 1 TIME 127 (of 200) ]
[ time 73 ] Run JOB 0 at PRIORITY 0 [ TICKS 6 ALLOT 1 TIME 126 (of 200) ]
[ time 74 ] Run JOB 0 at PRIORITY 0 [ TICKS 5 ALLOT 1 TIME 125 (of 200) ]
[ time 75 ] Run JOB 0 at PRIORITY 0 [ TICKS 4 ALLOT 1 TIME 124 (of 200) ]
[ time 76 ] Run JOB 0 at PRIORITY 0 [ TICKS 3 ALLOT 1 TIME 123 (of 200) ]
[ time 77 ] Run JOB 0 at PRIORITY 0 [ TICKS 2 ALLOT 1 TIME 122 (of 200) ]
[ time 78 ] Run JOB 0 at PRIORITY 0 [ TICKS 1 ALLOT 1 TIME 121 (of 200) ]
[ time 79 ] Run JOB 0 at PRIORITY 0 [ TICKS 0 ALLOT 1 TIME 120 (of 200) ]
[ time 80 ] Run JOB 0 at PRIORITY 0 [ TICKS 9 ALLOT 1 TIME 119 (of 200) ]
[ time 81 ] Run JOB 0 at PRIORITY 0 [ TICKS 8 ALLOT 1 TIME 118 (of 200) ]
[ time 82 ] Run JOB 0 at PRIORITY 0 [ TICKS 7 ALLOT 1 TIME 117 (of 200) ]
[ time 83 ] Run JOB 0 at PRIORITY 0 [ TICKS 6 ALLOT 1 TIME 116 (of 200) ]
[ time 84 ] Run JOB 0 at PRIORITY 0 [ TICKS 5 ALLOT 1 TIME 115 (of 200) ]
[ time 85 ] Run JOB 0 at PRIORITY 0 [ TICKS 4 ALLOT 1 TIME 114 (of 200) ]
[ time 86 ] Run JOB 0 at PRIORITY 0 [ TICKS 3 ALLOT 1 TIME 113 (of 200) ]
[ time 87 ] Run JOB 0 at PRIORITY 0 [ TICKS 2 ALLOT 1 TIME 112 (of 200) ]
[ time 88 ] Run JOB 0 at PRIORITY 0 [ TICKS 1 ALLOT 1 TIME 111 (of 200) ]
[ time 89 ] Run JOB 0 at PRIORITY 0 [ TICKS 0 ALLOT 1 TIME 110 (of 200) ]
[ time 90 ] Run JOB 0 at PRIORITY 0 [ TICKS 9 ALLOT 1 TIME 109 (of 200) ]
[ time 91 ] Run JOB 0 at PRIORITY 0 [ TICKS 8 ALLOT 1 TIME 108 (of 200) ]
[ time 92 ] Run JOB 0 at PRIORITY 0 [ TICKS 7 ALLOT 1 TIME 107 (of 200) ]
[ time 93 ] Run JOB 0 at PRIORITY 0 [ TICKS 6 ALLOT 1 TIME 106 (of 200) ]
[ time 94 ] Run JOB 0 at PRIORITY 0 [ TICKS 5 ALLOT 1 TIME 105 (of 200) ]
[ time 95 ] Run JOB 0 at PRIORITY 0 [ TICKS 4 ALLOT 1 TIME 104 (of 200) ]
[ time 96 ] Run JOB 0 at PRIORITY 0 [ TICKS 3 ALLOT 1 TIME 103 (of 200) ]
[ time 97 ] Run JOB 0 at PRIORITY 0 [ TICKS 2 ALLOT 1 TIME 102 (of 200) ]
[ time 98 ] Run JOB 0 at PRIORITY 0 [ TICKS 1 ALLOT 1 TIME 101 (of 200) ]
[ time 99 ] Run JOB 0 at PRIORITY 0 [ TICKS 0 ALLOT 1 TIME 100 (of 200) ]
[ time 100 ] BOOST ( every 50 )
[ time 100 ] JOB BEGINS by JOB 1
[ time 100 ] JOB BEGINS by JOB 2
[ time 100 ] Run JOB 0 at PRIORITY 2 [ TICKS 9 ALLOT 1 TIME 99 (of 200) ]
[ time 101 ] Run JOB 0 at PRIORITY 2 [ TICKS 8 ALLOT 1 TIME 98 (of 200) ]
[ time 102 ] Run JOB 0 at PRIORITY 2 [ TICKS 7 ALLOT 1 TIME 97 (of 200) ]
[ time 103 ] Run JOB 0 at PRIORITY 2 [ TICKS 6 ALLOT 1 TIME 96 (of 200) ]
[ time 104 ] Run JOB 0 at PRIORITY 2 [ TICKS 5 ALLOT 1 TIME 95 (of 200) ]
[ time 105 ] Run JOB 0 at PRIORITY 2 [ TICKS 4 ALLOT 1 TIME 94 (of 200) ]
[ time 106 ] Run JOB 0 at PRIORITY 2 [ TICKS 3 ALLOT 1 TIME 93 (of 200) ]
[ time 107 ] Run JOB 0 at PRIORITY 2 [ TICKS 2 ALLOT 1 TIME 92 (of 200) ]
[ time 108 ] Run JOB 0 at PRIORITY 2 [ TICKS 1 ALLOT 1 TIME 91 (of 200) ]
[ time 109 ] Run JOB 0 at PRIORITY 2 [ TICKS 0 ALLOT 1 TIME 90 (of 200) ]
[ time 110 ] Run JOB 1 at PRIORITY 2 [ TICKS 9 ALLOT 1 TIME 99 (of 100) ]
[ time 111 ] Run JOB 1 at PRIORITY 2 [ TICKS 8 ALLOT 1 TIME 98 (of 100) ]
[ time 112 ] Run JOB 1 at PRIORITY 2 [ TICKS 7 ALLOT 1 TIME 97 (of 100) ]
[ time 113 ] Run JOB 1 at PRIORITY 2 [ TICKS 6 ALLOT 1 TIME 96 (of 100) ]
[ time 114 ] Run JOB 1 at PRIORITY 2 [ TICKS 5 ALLOT 1 TIME 95 (of 100) ]
[ time 115 ] IO_START by JOB 1
IO DONE
[ time 115 ] Run JOB 2 at PRIORITY 2 [ TICKS 9 ALLOT 1 TIME 99 (of 100) ]
[ time 116 ] Run JOB 2 at PRIORITY 2 [ TICKS 8 ALLOT 1 TIME 98 (of 100) ]
[ time 117 ] Run JOB 2 at PRIORITY 2 [ TICKS 7 ALLOT 1 TIME 97 (of 100) ]
[ time 118 ] Run JOB 2 at PRIORITY 2 [ TICKS 6 ALLOT 1 TIME 96 (of 100) ]
[ time 119 ] Run JOB 2 at PRIORITY 2 [ TICKS 5 ALLOT 1 TIME 95 (of 100) ]
[ time 120 ] IO_START by JOB 2
IO DONE
[ time 120 ] IO_DONE by JOB 1
[ time 120 ] Run JOB 1 at PRIORITY 2 [ TICKS 9 ALLOT 1 TIME 94 (of 100) ]
[ time 121 ] Run JOB 1 at PRIORITY 2 [ TICKS 8 ALLOT 1 TIME 93 (of 100) ]
[ time 122 ] Run JOB 1 at PRIORITY 2 [ TICKS 7 ALLOT 1 TIME 92 (of 100) ]
[ time 123 ] Run JOB 1 at PRIORITY 2 [ TICKS 6 ALLOT 1 TIME 91 (of 100) ]
[ time 124 ] Run JOB 1 at PRIORITY 2 [ TICKS 5 ALLOT 1 TIME 90 (of 100) ]
[ time 125 ] IO_START by JOB 1
IO DONE
[ time 125 ] IO_DONE by JOB 2
[ time 125 ] Run JOB 2 at PRIORITY 2 [ TICKS 9 ALLOT 1 TIME 94 (of 100) ]
[ time 126 ] Run JOB 2 at PRIORITY 2 [ TICKS 8 ALLOT 1 TIME 93 (of 100) ]
[ time 127 ] Run JOB 2 at PRIORITY 2 [ TICKS 7 ALLOT 1 TIME 92 (of 100) ]
[ time 128 ] Run JOB 2 at PRIORITY 2 [ TICKS 6 ALLOT 1 TIME 91 (of 100) ]
[ time 129 ] Run JOB 2 at PRIORITY 2 [ TICKS 5 ALLOT 1 TIME 90 (of 100) ]
[ time 130 ] IO_START by JOB 2
IO DONE
[ time 130 ] IO_DONE by JOB 1
[ time 130 ] Run JOB 1 at PRIORITY 2 [ TICKS 9 ALLOT 1 TIME 89 (of 100) ]
[ time 131 ] Run JOB 1 at PRIORITY 2 [ TICKS 8 ALLOT 1 TIME 88 (of 100) ]
[ time 132 ] Run JOB 1 at PRIORITY 2 [ TICKS 7 ALLOT 1 TIME 87 (of 100) ]
[ time 133 ] Run JOB 1 at PRIORITY 2 [ TICKS 6 ALLOT 1 TIME 86 (of 100) ]
[ time 134 ] Run JOB 1 at PRIORITY 2 [ TICKS 5 ALLOT 1 TIME 85 (of 100) ]
[ time 135 ] IO_START by JOB 1
IO DONE
[ time 135 ] IO_DONE by JOB 2
[ time 135 ] Run JOB 2 at PRIORITY 2 [ TICKS 9 ALLOT 1 TIME 89 (of 100) ]
[ time 136 ] Run JOB 2 at PRIORITY 2 [ TICKS 8 ALLOT 1 TIME 88 (of 100) ]
[ time 137 ] Run JOB 2 at PRIORITY 2 [ TICKS 7 ALLOT 1 TIME 87 (of 100) ]
[ time 138 ] Run JOB 2 at PRIORITY 2 [ TICKS 6 ALLOT 1 TIME 86 (of 100) ]
[ time 139 ] Run JOB 2 at PRIORITY 2 [ TICKS 5 ALLOT 1 TIME 85 (of 100) ]
[ time 140 ] IO_START by JOB 2
IO DONE
[ time 140 ] IO_DONE by JOB 1
[ time 140 ] Run JOB 1 at PRIORITY 2 [ TICKS 9 ALLOT 1 TIME 84 (of 100) ]
[ time 141 ] Run JOB 1 at PRIORITY 2 [ TICKS 8 ALLOT 1 TIME 83 (of 100) ]
[ time 142 ] Run JOB 1 at PRIORITY 2 [ TICKS 7 ALLOT 1 TIME 82 (of 100) ]
[ time 143 ] Run JOB 1 at PRIORITY 2 [ TICKS 6 ALLOT 1 TIME 81 (of 100) ]
[ time 144 ] Run JOB 1 at PRIORITY 2 [ TICKS 5 ALLOT 1 TIME 80 (of 100) ]
[ time 145 ] IO_START by JOB 1
IO DONE
[ time 145 ] IO_DONE by JOB 2
[ time 145 ] Run JOB 2 at PRIORITY 2 [ TICKS 9 ALLOT 1 TIME 84 (of 100) ]
[ time 146 ] Run JOB 2 at PRIORITY 2 [ TICKS 8 ALLOT 1 TIME 83 (of 100) ]
[ time 147 ] Run JOB 2 at PRIORITY 2 [ TICKS 7 ALLOT 1 TIME 82 (of 100) ]
[ time 148 ] Run JOB 2 at PRIORITY 2 [ TICKS 6 ALLOT 1 TIME 81 (of 100) ]
[ time 149 ] Run JOB 2 at PRIORITY 2 [ TICKS 5 ALLOT 1 TIME 80 (of 100) ]
[ time 150 ] IO_START by JOB 2
IO DONE
[ time 150 ] BOOST ( every 50 )
[ time 150 ] IO_DONE by JOB 1
[ time 150 ] Run JOB 0 at PRIORITY 2 [ TICKS 9 ALLOT 1 TIME 89 (of 200) ]
[ time 151 ] Run JOB 0 at PRIORITY 2 [ TICKS 8 ALLOT 1 TIME 88 (of 200) ]
[ time 152 ] Run JOB 0 at PRIORITY 2 [ TICKS 7 ALLOT 1 TIME 87 (of 200) ]
[ time 153 ] Run JOB 0 at PRIORITY 2 [ TICKS 6 ALLOT 1 TIME 86 (of 200) ]
[ time 154 ] Run JOB 0 at PRIORITY 2 [ TICKS 5 ALLOT 1 TIME 85 (of 200) ]
[ time 155 ] IO_DONE by JOB 2
[ time 155 ] Run JOB 0 at PRIORITY 2 [ TICKS 4 ALLOT 1 TIME 84 (of 200) ]
[ time 156 ] Run JOB 0 at PRIORITY 2 [ TICKS 3 ALLOT 1 TIME 83 (of 200) ]
[ time 157 ] Run JOB 0 at PRIORITY 2 [ TICKS 2 ALLOT 1 TIME 82 (of 200) ]
[ time 158 ] Run JOB 0 at PRIORITY 2 [ TICKS 1 ALLOT 1 TIME 81 (of 200) ]
[ time 159 ] Run JOB 0 at PRIORITY 2 [ TICKS 0 ALLOT 1 TIME 80 (of 200) ]
[ time 160 ] Run JOB 1 at PRIORITY 2 [ TICKS 9 ALLOT 1 TIME 79 (of 100) ]
[ time 161 ] Run JOB 1 at PRIORITY 2 [ TICKS 8 ALLOT 1 TIME 78 (of 100) ]
[ time 162 ] Run JOB 1 at PRIORITY 2 [ TICKS 7 ALLOT 1 TIME 77 (of 100) ]
[ time 163 ] Run JOB 1 at PRIORITY 2 [ TICKS 6 ALLOT 1 TIME 76 (of 100) ]
[ time 164 ] Run JOB 1 at PRIORITY 2 [ TICKS 5 ALLOT 1 TIME 75 (of 100) ]
[ time 165 ] IO_START by JOB 1
IO DONE
[ time 165 ] Run JOB 2 at PRIORITY 2 [ TICKS 9 ALLOT 1 TIME 79 (of 100) ]
[ time 166 ] Run JOB 2 at PRIORITY 2 [ TICKS 8 ALLOT 1 TIME 78 (of 100) ]
[ time 167 ] Run JOB 2 at PRIORITY 2 [ TICKS 7 ALLOT 1 TIME 77 (of 100) ]
[ time 168 ] Run JOB 2 at PRIORITY 2 [ TICKS 6 ALLOT 1 TIME 76 (of 100) ]
[ time 169 ] Run JOB 2 at PRIORITY 2 [ TICKS 5 ALLOT 1 TIME 75 (of 100) ]
[ time 170 ] IO_START by JOB 2
IO DONE
[ time 170 ] IO_DONE by JOB 1
[ time 170 ] Run JOB 1 at PRIORITY 2 [ TICKS 9 ALLOT 1 TIME 74 (of 100) ]
[ time 171 ] Run JOB 1 at PRIORITY 2 [ TICKS 8 ALLOT 1 TIME 73 (of 100) ]
[ time 172 ] Run JOB 1 at PRIORITY 2 [ TICKS 7 ALLOT 1 TIME 72 (of 100) ]
[ time 173 ] Run JOB 1 at PRIORITY 2 [ TICKS 6 ALLOT 1 TIME 71 (of 100) ]
[ time 174 ] Run JOB 1 at PRIORITY 2 [ TICKS 5 ALLOT 1 TIME 70 (of 100) ]
[ time 175 ] IO_START by JOB 1
IO DONE
[ time 175 ] IO_DONE by JOB 2
[ time 175 ] Run JOB 2 at PRIORITY 2 [ TICKS 9 ALLOT 1 TIME 74 (of 100) ]
[ time 176 ] Run JOB 2 at PRIORITY 2 [ TICKS 8 ALLOT 1 TIME 73 (of 100) ]
[ time 177 ] Run JOB 2 at PRIORITY 2 [ TICKS 7 ALLOT 1 TIME 72 (of 100) ]
[ time 178 ] Run JOB 2 at PRIORITY 2 [ TICKS 6 ALLOT 1 TIME 71 (of 100) ]
[ time 179 ] Run JOB 2 at PRIORITY 2 [ TICKS 5 ALLOT 1 TIME 70 (of 100) ]
[ time 180 ] IO_START by JOB 2
IO DONE
[ time 180 ] IO_DONE by JOB 1
[ time 180 ] Run JOB 1 at PRIORITY 2 [ TICKS 9 ALLOT 1 TIME 69 (of 100) ]
[ time 181 ] Run JOB 1 at PRIORITY 2 [ TICKS 8 ALLOT 1 TIME 68 (of 100) ]
[ time 182 ] Run JOB 1 at PRIORITY 2 [ TICKS 7 ALLOT 1 TIME 67 (of 100) ]
[ time 183 ] Run JOB 1 at PRIORITY 2 [ TICKS 6 ALLOT 1 TIME 66 (of 100) ]
[ time 184 ] Run JOB 1 at PRIORITY 2 [ TICKS 5 ALLOT 1 TIME 65 (of 100) ]
[ time 185 ] IO_START by JOB 1
IO DONE
[ time 185 ] IO_DONE by JOB 2
[ time 185 ] Run JOB 2 at PRIORITY 2 [ TICKS 9 ALLOT 1 TIME 69 (of 100) ]
[ time 186 ] Run JOB 2 at PRIORITY 2 [ TICKS 8 ALLOT 1 TIME 68 (of 100) ]
[ time 187 ] Run JOB 2 at PRIORITY 2 [ TICKS 7 ALLOT 1 TIME 67 (of 100) ]
[ time 188 ] Run JOB 2 at PRIORITY 2 [ TICKS 6 ALLOT 1 TIME 66 (of 100) ]
[ time 189 ] Run JOB 2 at PRIORITY 2 [ TICKS 5 ALLOT 1 TIME 65 (of 100) ]
[ time 190 ] IO_START by JOB 2
IO DONE
[ time 190 ] IO_DONE by JOB 1
[ time 190 ] Run JOB 1 at PRIORITY 2 [ TICKS 9 ALLOT 1 TIME 64 (of 100) ]
[ time 191 ] Run JOB 1 at PRIORITY 2 [ TICKS 8 ALLOT 1 TIME 63 (of 100) ]
[ time 192 ] Run JOB 1 at PRIORITY 2 [ TICKS 7 ALLOT 1 TIME 62 (of 100) ]
[ time 193 ] Run JOB 1 at PRIORITY 2 [ TICKS 6 ALLOT 1 TIME 61 (of 100) ]
[ time 194 ] Run JOB 1 at PRIORITY 2 [ TICKS 5 ALLOT 1 TIME 60 (of 100) ]
[ time 195 ] IO_START by JOB 1
IO DONE
[ time 195 ] IO_DONE by JOB 2
[ time 195 ] Run JOB 2 at PRIORITY 2 [ TICKS 9 ALLOT 1 TIME 64 (of 100) ]
[ time 196 ] Run JOB 2 at PRIORITY 2 [ TICKS 8 ALLOT 1 TIME 63 (of 100) ]
[ time 197 ] Run JOB 2 at PRIORITY 2 [ TICKS 7 ALLOT 1 TIME 62 (of 100) ]
[ time 198 ] Run JOB 2 at PRIORITY 2 [ TICKS 6 ALLOT 1 TIME 61 (of 100) ]
[ time 199 ] Run JOB 2 at PRIORITY 2 [ TICKS 5 ALLOT 1 TIME 60 (of 100) ]
[ time 200 ] IO_START by JOB 2
IO DONE
[ time 200 ] BOOST ( every 50 )
[ time 200 ] IO_DONE by JOB 1
[ time 200 ] Run JOB 0 at PRIORITY 2 [ TICKS 9 ALLOT 1 TIME 79 (of 200) ]
[ time 201 ] Run JOB 0 at PRIORITY 2 [ TICKS 8 ALLOT 1 TIME 78 (of 200) ]
[ time 202 ] Run JOB 0 at PRIORITY 2 [ TICKS 7 ALLOT 1 TIME 77 (of 200) ]
[ time 203 ] Run JOB 0 at PRIORITY 2 [ TICKS 6 ALLOT 1 TIME 76 (of 200) ]
[ time 204 ] Run JOB 0 at PRIORITY 2 [ TICKS 5 ALLOT 1 TIME 75 (of 200) ]
[ time 205 ] IO_DONE by JOB 2
[ time 205 ] Run JOB 0 at PRIORITY 2 [ TICKS 4 ALLOT 1 TIME 74 (of 200) ]
[ time 206 ] Run JOB 0 at PRIORITY 2 [ TICKS 3 ALLOT 1 TIME 73 (of 200) ]
[ time 207 ] Run JOB 0 at PRIORITY 2 [ TICKS 2 ALLOT 1 TIME 72 (of 200) ]
[ time 208 ] Run JOB 0 at PRIORITY 2 [ TICKS 1 ALLOT 1 TIME 71 (of 200) ]
[ time 209 ] Run JOB 0 at PRIORITY 2 [ TICKS 0 ALLOT 1 TIME 70 (of 200) ]
[ time 210 ] Run JOB 1 at PRIORITY 2 [ TICKS 9 ALLOT 1 TIME 59 (of 100) ]
[ time 211 ] Run JOB 1 at PRIORITY 2 [ TICKS 8 ALLOT 1 TIME 58 (of 100) ]
[ time 212 ] Run JOB 1 at PRIORITY 2 [ TICKS 7 ALLOT 1 TIME 57 (of 100) ]
[ time 213 ] Run JOB 1 at PRIORITY 2 [ TICKS 6 ALLOT 1 TIME 56 (of 100) ]
[ time 214 ] Run JOB 1 at PRIORITY 2 [ TICKS 5 ALLOT 1 TIME 55 (of 100) ]
[ time 215 ] IO_START by JOB 1
IO DONE
[ time 215 ] Run JOB 2 at PRIORITY 2 [ TICKS 9 ALLOT 1 TIME 59 (of 100) ]
[ time 216 ] Run JOB 2 at PRIORITY 2 [ TICKS 8 ALLOT 1 TIME 58 (of 100) ]
[ time 217 ] Run JOB 2 at PRIORITY 2 [ TICKS 7 ALLOT 1 TIME 57 (of 100) ]
[ time 218 ] Run JOB 2 at PRIORITY 2 [ TICKS 6 ALLOT 1 TIME 56 (of 100) ]
[ time 219 ] Run JOB 2 at PRIORITY 2 [ TICKS 5 ALLOT 1 TIME 55 (of 100) ]
[ time 220 ] IO_START by JOB 2
IO DONE
[ time 220 ] IO_DONE by JOB 1
[ time 220 ] Run JOB 1 at PRIORITY 2 [ TICKS 9 ALLOT 1 TIME 54 (of 100) ]
[ time 221 ] Run JOB 1 at PRIORITY 2 [ TICKS 8 ALLOT 1 TIME 53 (of 100) ]
[ time 222 ] Run JOB 1 at PRIORITY 2 [ TICKS 7 ALLOT 1 TIME 52 (of 100) ]
[ time 223 ] Run JOB 1 at PRIORITY 2 [ TICKS 6 ALLOT 1 TIME 51 (of 100) ]
[ time 224 ] Run JOB 1 at PRIORITY 2 [ TICKS 5 ALLOT 1 TIME 50 (of 100) ]
[ time 225 ] IO_START by JOB 1
IO DONE
[ time 225 ] IO_DONE by JOB 2
[ time 225 ] Run JOB 2 at PRIORITY 2 [ TICKS 9 ALLOT 1 TIME 54 (of 100) ]
[ time 226 ] Run JOB 2 at PRIORITY 2 [ TICKS 8 ALLOT 1 TIME 53 (of 100) ]
[ time 227 ] Run JOB 2 at PRIORITY 2 [ TICKS 7 ALLOT 1 TIME 52 (of 100) ]
[ time 228 ] Run JOB 2 at PRIORITY 2 [ TICKS 6 ALLOT 1 TIME 51 (of 100) ]
[ time 229 ] Run JOB 2 at PRIORITY 2 [ TICKS 5 ALLOT 1 TIME 50 (of 100) ]
[ time 230 ] IO_START by JOB 2
IO DONE
[ time 230 ] IO_DONE by JOB 1
[ time 230 ] Run JOB 1 at PRIORITY 2 [ TICKS 9 ALLOT 1 TIME 49 (of 100) ]
[ time 231 ] Run JOB 1 at PRIORITY 2 [ TICKS 8 ALLOT 1 TIME 48 (of 100) ]
[ time 232 ] Run JOB 1 at PRIORITY 2 [ TICKS 7 ALLOT 1 TIME 47 (of 100) ]
[ time 233 ] Run JOB 1 at PRIORITY 2 [ TICKS 6 ALLOT 1 TIME 46 (of 100) ]
[ time 234 ] Run JOB 1 at PRIORITY 2 [ TICKS 5 ALLOT 1 TIME 45 (of 100) ]
[ time 235 ] IO_START by JOB 1
IO DONE
[ time 235 ] IO_DONE by JOB 2
[ time 235 ] Run JOB 2 at PRIORITY 2 [ TICKS 9 ALLOT 1 TIME 49 (of 100) ]
[ time 236 ] Run JOB 2 at PRIORITY 2 [ TICKS 8 ALLOT 1 TIME 48 (of 100) ]
[ time 237 ] Run JOB 2 at PRIORITY 2 [ TICKS 7 ALLOT 1 TIME 47 (of 100) ]
[ time 238 ] Run JOB 2 at PRIORITY 2 [ TICKS 6 ALLOT 1 TIME 46 (of 100) ]
[ time 239 ] Run JOB 2 at PRIORITY 2 [ TICKS 5 ALLOT 1 TIME 45 (of 100) ]
[ time 240 ] IO_START by JOB 2
IO DONE
[ time 240 ] IO_DONE by JOB 1
[ time 240 ] Run JOB 1 at PRIORITY 2 [ TICKS 9 ALLOT 1 TIME 44 (of 100) ]
[ time 241 ] Run JOB 1 at PRIORITY 2 [ TICKS 8 ALLOT 1 TIME 43 (of 100) ]
[ time 242 ] Run JOB 1 at PRIORITY 2 [ TICKS 7 ALLOT 1 TIME 42 (of 100) ]
[ time 243 ] Run JOB 1 at PRIORITY 2 [ TICKS 6 ALLOT 1 TIME 41 (of 100) ]
[ time 244 ] Run JOB 1 at PRIORITY 2 [ TICKS 5 ALLOT 1 TIME 40 (of 100) ]
[ time 245 ] IO_START by JOB 1
IO DONE
[ time 245 ] IO_DONE by JOB 2
[ time 245 ] Run JOB 2 at PRIORITY 2 [ TICKS 9 ALLOT 1 TIME 44 (of 100) ]
[ time 246 ] Run JOB 2 at PRIORITY 2 [ TICKS 8 ALLOT 1 TIME 43 (of 100) ]
[ time 247 ] Run JOB 2 at PRIORITY 2 [ TICKS 7 ALLOT 1 TIME 42 (of 100) ]
[ time 248 ] Run JOB 2 at PRIORITY 2 [ TICKS 6 ALLOT 1 TIME 41 (of 100) ]
[ time 249 ] Run JOB 2 at PRIORITY 2 [ TICKS 5 ALLOT 1 TIME 40 (of 100) ]
[ time 250 ] IO_START by JOB 2
IO DONE
[ time 250 ] BOOST ( every 50 )
[ time 250 ] IO_DONE by JOB 1
[ time 250 ] Run JOB 0 at PRIORITY 2 [ TICKS 9 ALLOT 1 TIME 69 (of 200) ]
[ time 251 ] Run JOB 0 at PRIORITY 2 [ TICKS 8 ALLOT 1 TIME 68 (of 200) ]
[ time 252 ] Run JOB 0 at PRIORITY 2 [ TICKS 7 ALLOT 1 TIME 67 (of 200) ]
[ time 253 ] Run JOB 0 at PRIORITY 2 [ TICKS 6 ALLOT 1 TIME 66 (of 200) ]
[ time 254 ] Run JOB 0 at PRIORITY 2 [ TICKS 5 ALLOT 1 TIME 65 (of 200) ]
[ time 255 ] IO_DONE by JOB 2
[ time 255 ] Run JOB 0 at PRIORITY 2 [ TICKS 4 ALLOT 1 TIME 64 (of 200) ]
[ time 256 ] Run JOB 0 at PRIORITY 2 [ TICKS 3 ALLOT 1 TIME 63 (of 200) ]
[ time 257 ] Run JOB 0 at PRIORITY 2 [ TICKS 2 ALLOT 1 TIME 62 (of 200) ]
[ time 258 ] Run JOB 0 at PRIORITY 2 [ TICKS 1 ALLOT 1 TIME 61 (of 200) ]
[ time 259 ] Run JOB 0 at PRIORITY 2 [ TICKS 0 ALLOT 1 TIME 60 (of 200) ]
[ time 260 ] Run JOB 1 at PRIORITY 2 [ TICKS 9 ALLOT 1 TIME 39 (of 100) ]
[ time 261 ] Run JOB 1 at PRIORITY 2 [ TICKS 8 ALLOT 1 TIME 38 (of 100) ]
[ time 262 ] Run JOB 1 at PRIORITY 2 [ TICKS 7 ALLOT 1 TIME 37 (of 100) ]
[ time 263 ] Run JOB 1 at PRIORITY 2 [ TICKS 6 ALLOT 1 TIME 36 (of 100) ]
[ time 264 ] Run JOB 1 at PRIORITY 2 [ TICKS 5 ALLOT 1 TIME 35 (of 100) ]
[ time 265 ] IO_START by JOB 1
IO DONE
[ time 265 ] Run JOB 2 at PRIORITY 2 [ TICKS 9 ALLOT 1 TIME 39 (of 100) ]
[ time 266 ] Run JOB 2 at PRIORITY 2 [ TICKS 8 ALLOT 1 TIME 38 (of 100) ]
[ time 267 ] Run JOB 2 at PRIORITY 2 [ TICKS 7 ALLOT 1 TIME 37 (of 100) ]
[ time 268 ] Run JOB 2 at PRIORITY 2 [ TICKS 6 ALLOT 1 TIME 36 (of 100) ]
[ time 269 ] Run JOB 2 at PRIORITY 2 [ TICKS 5 ALLOT 1 TIME 35 (of 100) ]
[ time 270 ] IO_START by JOB 2
IO DONE
[ time 270 ] IO_DONE by JOB 1
[ time 270 ] Run JOB 1 at PRIORITY 2 [ TICKS 9 ALLOT 1 TIME 34 (of 100) ]
[ time 271 ] Run JOB 1 at PRIORITY 2 [ TICKS 8 ALLOT 1 TIME 33 (of 100) ]
[ time 272 ] Run JOB 1 at PRIORITY 2 [ TICKS 7 ALLOT 1 TIME 32 (of 100) ]
[ time 273 ] Run JOB 1 at PRIORITY 2 [ TICKS 6 ALLOT 1 TIME 31 (of 100) ]
[ time 274 ] Run JOB 1 at PRIORITY 2 [ TICKS 5 ALLOT 1 TIME 30 (of 100) ]
[ time 275 ] IO_START by JOB 1
IO DONE
[ time 275 ] IO_DONE by JOB 2
[ time 275 ] Run JOB 2 at PRIORITY 2 [ TICKS 9 ALLOT 1 TIME 34 (of 100) ]
[ time 276 ] Run JOB 2 at PRIORITY 2 [ TICKS 8 ALLOT 1 TIME 33 (of 100) ]
[ time 277 ] Run JOB 2 at PRIORITY 2 [ TICKS 7 ALLOT 1 TIME 32 (of 100) ]
[ time 278 ] Run JOB 2 at PRIORITY 2 [ TICKS 6 ALLOT 1 TIME 31 (of 100) ]
[ time 279 ] Run JOB 2 at PRIORITY 2 [ TICKS 5 ALLOT 1 TIME 30 (of 100) ]
[ time 280 ] IO_START by JOB 2
IO DONE
[ time 280 ] IO_DONE by JOB 1
[ time 280 ] Run JOB 1 at PRIORITY 2 [ TICKS 9 ALLOT 1 TIME 29 (of 100) ]
[ time 281 ] Run JOB 1 at PRIORITY 2 [ TICKS 8 ALLOT 1 TIME 28 (of 100) ]
[ time 282 ] Run JOB 1 at PRIORITY 2 [ TICKS 7 ALLOT 1 TIME 27 (of 100) ]
[ time 283 ] Run JOB 1 at PRIORITY 2 [ TICKS 6 ALLOT 1 TIME 26 (of 100) ]
[ time 284 ] Run JOB 1 at PRIORITY 2 [ TICKS 5 ALLOT 1 TIME 25 (of 100) ]
[ time 285 ] IO_START by JOB 1
IO DONE
[ time 285 ] IO_DONE by JOB 2
[ time 285 ] Run JOB 2 at PRIORITY 2 [ TICKS 9 ALLOT 1 TIME 29 (of 100) ]
[ time 286 ] Run JOB 2 at PRIORITY 2 [ TICKS 8 ALLOT 1 TIME 28 (of 100) ]
[ time 287 ] Run JOB 2 at PRIORITY 2 [ TICKS 7 ALLOT 1 TIME 27 (of 100) ]
[ time 288 ] Run JOB 2 at PRIORITY 2 [ TICKS 6 ALLOT 1 TIME 26 (of 100) ]
[ time 289 ] Run JOB 2 at PRIORITY 2 [ TICKS 5 ALLOT 1 TIME 25 (of 100) ]
[ time 290 ] IO_START by JOB 2
IO DONE
[ time 290 ] IO_DONE by JOB 1
[ time 290 ] Run JOB 1 at PRIORITY 2 [ TICKS 9 ALLOT 1 TIME 24 (of 100) ]
[ time 291 ] Run JOB 1 at PRIORITY 2 [ TICKS 8 ALLOT 1 TIME 23 (of 100) ]
[ time 292 ] Run JOB 1 at PRIORITY 2 [ TICKS 7 ALLOT 1 TIME 22 (of 100) ]
[ time 293 ] Run JOB 1 at PRIORITY 2 [ TICKS 6 ALLOT 1 TIME 21 (of 100) ]
[ time 294 ] Run JOB 1 at PRIORITY 2 [ TICKS 5 ALLOT 1 TIME 20 (of 100) ]
[ time 295 ] IO_START by JOB 1
IO DONE
[ time 295 ] IO_DONE by JOB 2
[ time 295 ] Run JOB 2 at PRIORITY 2 [ TICKS 9 ALLOT 1 TIME 24 (of 100) ]
[ time 296 ] Run JOB 2 at PRIORITY 2 [ TICKS 8 ALLOT 1 TIME 23 (of 100) ]
[ time 297 ] Run JOB 2 at PRIORITY 2 [ TICKS 7 ALLOT 1 TIME 22 (of 100) ]
[ time 298 ] Run JOB 2 at PRIORITY 2 [ TICKS 6 ALLOT 1 TIME 21 (of 100) ]
[ time 299 ] Run JOB 2 at PRIORITY 2 [ TICKS 5 ALLOT 1 TIME 20 (of 100) ]
[ time 300 ] IO_START by JOB 2
IO DONE
[ time 300 ] BOOST ( every 50 )
[ time 300 ] IO_DONE by JOB 1
[ time 300 ] Run JOB 0 at PRIORITY 2 [ TICKS 9 ALLOT 1 TIME 59 (of 200) ]
[ time 301 ] Run JOB 0 at PRIORITY 2 [ TICKS 8 ALLOT 1 TIME 58 (of 200) ]
[ time 302 ] Run JOB 0 at PRIORITY 2 [ TICKS 7 ALLOT 1 TIME 57 (of 200) ]
[ time 303 ] Run JOB 0 at PRIORITY 2 [ TICKS 6 ALLOT 1 TIME 56 (of 200) ]
[ time 304 ] Run JOB 0 at PRIORITY 2 [ TICKS 5 ALLOT 1 TIME 55 (of 200) ]
[ time 305 ] IO_DONE by JOB 2
[ time 305 ] Run JOB 0 at PRIORITY 2 [ TICKS 4 ALLOT 1 TIME 54 (of 200) ]
[ time 306 ] Run JOB 0 at PRIORITY 2 [ TICKS 3 ALLOT 1 TIME 53 (of 200) ]
[ time 307 ] Run JOB 0 at PRIORITY 2 [ TICKS 2 ALLOT 1 TIME 52 (of 200) ]
[ time 308 ] Run JOB 0 at PRIORITY 2 [ TICKS 1 ALLOT 1 TIME 51 (of 200) ]
[ time 309 ] Run JOB 0 at PRIORITY 2 [ TICKS 0 ALLOT 1 TIME 50 (of 200) ]
[ time 310 ] Run JOB 1 at PRIORITY 2 [ TICKS 9 ALLOT 1 TIME 19 (of 100) ]
[ time 311 ] Run JOB 1 at PRIORITY 2 [ TICKS 8 ALLOT 1 TIME 18 (of 100) ]
[ time 312 ] Run JOB 1 at PRIORITY 2 [ TICKS 7 ALLOT 1 TIME 17 (of 100) ]
[ time 313 ] Run JOB 1 at PRIORITY 2 [ TICKS 6 ALLOT 1 TIME 16 (of 100) ]
[ time 314 ] Run JOB 1 at PRIORITY 2 [ TICKS 5 ALLOT 1 TIME 15 (of 100) ]
[ time 315 ] IO_START by JOB 1
IO DONE
[ time 315 ] Run JOB 2 at PRIORITY 2 [ TICKS 9 ALLOT 1 TIME 19 (of 100) ]
[ time 316 ] Run JOB 2 at PRIORITY 2 [ TICKS 8 ALLOT 1 TIME 18 (of 100) ]
[ time 317 ] Run JOB 2 at PRIORITY 2 [ TICKS 7 ALLOT 1 TIME 17 (of 100) ]
[ time 318 ] Run JOB 2 at PRIORITY 2 [ TICKS 6 ALLOT 1 TIME 16 (of 100) ]
[ time 319 ] Run JOB 2 at PRIORITY 2 [ TICKS 5 ALLOT 1 TIME 15 (of 100) ]
[ time 320 ] IO_START by JOB 2
IO DONE
[ time 320 ] IO_DONE by JOB 1
[ time 320 ] Run JOB 1 at PRIORITY 2 [ TICKS 9 ALLOT 1 TIME 14 (of 100) ]
[ time 321 ] Run JOB 1 at PRIORITY 2 [ TICKS 8 ALLOT 1 TIME 13 (of 100) ]
[ time 322 ] Run JOB 1 at PRIORITY 2 [ TICKS 7 ALLOT 1 TIME 12 (of 100) ]
[ time 323 ] Run JOB 1 at PRIORITY 2 [ TICKS 6 ALLOT 1 TIME 11 (of 100) ]
[ time 324 ] Run JOB 1 at PRIORITY 2 [ TICKS 5 ALLOT 1 TIME 10 (of 100) ]
[ time 325 ] IO_START by JOB 1
IO DONE
[ time 325 ] IO_DONE by JOB 2
[ time 325 ] Run JOB 2 at PRIORITY 2 [ TICKS 9 ALLOT 1 TIME 14 (of 100) ]
[ time 326 ] Run JOB 2 at PRIORITY 2 [ TICKS 8 ALLOT 1 TIME 13 (of 100) ]
[ time 327 ] Run JOB 2 at PRIORITY 2 [ TICKS 7 ALLOT 1 TIME 12 (of 100) ]
[ time 328 ] Run JOB 2 at PRIORITY 2 [ TICKS 6 ALLOT 1 TIME 11 (of 100) ]
[ time 329 ] Run JOB 2 at PRIORITY 2 [ TICKS 5 ALLOT 1 TIME 10 (of 100) ]
[ time 330 ] IO_START by JOB 2
IO DONE
[ time 330 ] IO_DONE by JOB 1
[ time 330 ] Run JOB 1 at PRIORITY 2 [ TICKS 9 ALLOT 1 TIME 9 (of 100) ]
[ time 331 ] Run JOB 1 at PRIORITY 2 [ TICKS 8 ALLOT 1 TIME 8 (of 100) ]
[ time 332 ] Run JOB 1 at PRIORITY 2 [ TICKS 7 ALLOT 1 TIME 7 (of 100) ]
[ time 333 ] Run JOB 1 at PRIORITY 2 [ TICKS 6 ALLOT 1 TIME 6 (of 100) ]
[ time 334 ] Run JOB 1 at PRIORITY 2 [ TICKS 5 ALLOT 1 TIME 5 (of 100) ]
[ time 335 ] IO_START by JOB 1
IO DONE
[ time 335 ] IO_DONE by JOB 2
[ time 335 ] Run JOB 2 at PRIORITY 2 [ TICKS 9 ALLOT 1 TIME 9 (of 100) ]
[ time 336 ] Run JOB 2 at PRIORITY 2 [ TICKS 8 ALLOT 1 TIME 8 (of 100) ]
[ time 337 ] Run JOB 2 at PRIORITY 2 [ TICKS 7 ALLOT 1 TIME 7 (of 100) ]
[ time 338 ] Run JOB 2 at PRIORITY 2 [ TICKS 6 ALLOT 1 TIME 6 (of 100) ]
[ time 339 ] Run JOB 2 at PRIORITY 2 [ TICKS 5 ALLOT 1 TIME 5 (of 100) ]
[ time 340 ] IO_START by JOB 2
IO DONE
[ time 340 ] IO_DONE by JOB 1
[ time 340 ] Run JOB 1 at PRIORITY 2 [ TICKS 9 ALLOT 1 TIME 4 (of 100) ]
[ time 341 ] Run JOB 1 at PRIORITY 2 [ TICKS 8 ALLOT 1 TIME 3 (of 100) ]
[ time 342 ] Run JOB 1 at PRIORITY 2 [ TICKS 7 ALLOT 1 TIME 2 (of 100) ]
[ time 343 ] Run JOB 1 at PRIORITY 2 [ TICKS 6 ALLOT 1 TIME 1 (of 100) ]
[ time 344 ] Run JOB 1 at PRIORITY 2 [ TICKS 5 ALLOT 1 TIME 0 (of 100) ]
[ time 345 ] FINISHED JOB 1
[ time 345 ] IO_DONE by JOB 2
[ time 345 ] Run JOB 2 at PRIORITY 2 [ TICKS 9 ALLOT 1 TIME 4 (of 100) ]
[ time 346 ] Run JOB 2 at PRIORITY 2 [ TICKS 8 ALLOT 1 TIME 3 (of 100) ]
[ time 347 ] Run JOB 2 at PRIORITY 2 [ TICKS 7 ALLOT 1 TIME 2 (of 100) ]
[ time 348 ] Run JOB 2 at PRIORITY 2 [ TICKS 6 ALLOT 1 TIME 1 (of 100) ]
[ time 349 ] Run JOB 2 at PRIORITY 2 [ TICKS 5 ALLOT 1 TIME 0 (of 100) ]
[ time 350 ] FINISHED JOB 2
[ time 350 ] BOOST ( every 50 )
[ time 350 ] Run JOB 0 at PRIORITY 2 [ TICKS 9 ALLOT 1 TIME 49 (of 200) ]
[ time 351 ] Run JOB 0 at PRIORITY 2 [ TICKS 8 ALLOT 1 TIME 48 (of 200) ]
[ time 352 ] Run JOB 0 at PRIORITY 2 [ TICKS 7 ALLOT 1 TIME 47 (of 200) ]
[ time 353 ] Run JOB 0 at PRIORITY 2 [ TICKS 6 ALLOT 1 TIME 46 (of 200) ]
[ time 354 ] Run JOB 0 at PRIORITY 2 [ TICKS 5 ALLOT 1 TIME 45 (of 200) ]
[ time 355 ] Run JOB 0 at PRIORITY 2 [ TICKS 4 ALLOT 1 TIME 44 (of 200) ]
[ time 356 ] Run JOB 0 at PRIORITY 2 [ TICKS 3 ALLOT 1 TIME 43 (of 200) ]
[ time 357 ] Run JOB 0 at PRIORITY 2 [ TICKS 2 ALLOT 1 TIME 42 (of 200) ]
[ time 358 ] Run JOB 0 at PRIORITY 2 [ TICKS 1 ALLOT 1 TIME 41 (of 200) ]
[ time 359 ] Run JOB 0 at PRIORITY 2 [ TICKS 0 ALLOT 1 TIME 40 (of 200) ]
[ time 360 ] Run JOB 0 at PRIORITY 1 [ TICKS 9 ALLOT 1 TIME 39 (of 200) ]
[ time 361 ] Run JOB 0 at PRIORITY 1 [ TICKS 8 ALLOT 1 TIME 38 (of 200) ]
[ time 362 ] Run JOB 0 at PRIORITY 1 [ TICKS 7 ALLOT 1 TIME 37 (of 200) ]
[ time 363 ] Run JOB 0 at PRIORITY 1 [ TICKS 6 ALLOT 1 TIME 36 (of 200) ]
[ time 364 ] Run JOB 0 at PRIORITY 1 [ TICKS 5 ALLOT 1 TIME 35 (of 200) ]
[ time 365 ] Run JOB 0 at PRIORITY 1 [ TICKS 4 ALLOT 1 TIME 34 (of 200) ]
[ time 366 ] Run JOB 0 at PRIORITY 1 [ TICKS 3 ALLOT 1 TIME 33 (of 200) ]
[ time 367 ] Run JOB 0 at PRIORITY 1 [ TICKS 2 ALLOT 1 TIME 32 (of 200) ]
[ time 368 ] Run JOB 0 at PRIORITY 1 [ TICKS 1 ALLOT 1 TIME 31 (of 200) ]
[ time 369 ] Run JOB 0 at PRIORITY 1 [ TICKS 0 ALLOT 1 TIME 30 (of 200) ]
[ time 370 ] Run JOB 0 at PRIORITY 0 [ TICKS 9 ALLOT 1 TIME 29 (of 200) ]
[ time 371 ] Run JOB 0 at PRIORITY 0 [ TICKS 8 ALLOT 1 TIME 28 (of 200) ]
[ time 372 ] Run JOB 0 at PRIORITY 0 [ TICKS 7 ALLOT 1 TIME 27 (of 200) ]
[ time 373 ] Run JOB 0 at PRIORITY 0 [ TICKS 6 ALLOT 1 TIME 26 (of 200) ]
[ time 374 ] Run JOB 0 at PRIORITY 0 [ TICKS 5 ALLOT 1 TIME 25 (of 200) ]
[ time 375 ] Run JOB 0 at PRIORITY 0 [ TICKS 4 ALLOT 1 TIME 24 (of 200) ]
[ time 376 ] Run JOB 0 at PRIORITY 0 [ TICKS 3 ALLOT 1 TIME 23 (of 200) ]
[ time 377 ] Run JOB 0 at PRIORITY 0 [ TICKS 2 ALLOT 1 TIME 22 (of 200) ]
[ time 378 ] Run JOB 0 at PRIORITY 0 [ TICKS 1 ALLOT 1 TIME 21 (of 200) ]
[ time 379 ] Run JOB 0 at PRIORITY 0 [ TICKS 0 ALLOT 1 TIME 20 (of 200) ]
[ time 380 ] Run JOB 0 at PRIORITY 0 [ TICKS 9 ALLOT 1 TIME 19 (of 200) ]
[ time 381 ] Run JOB 0 at PRIORITY 0 [ TICKS 8 ALLOT 1 TIME 18 (of 200) ]
[ time 382 ] Run JOB 0 at PRIORITY 0 [ TICKS 7 ALLOT 1 TIME 17 (of 200) ]
[ time 383 ] Run JOB 0 at PRIORITY 0 [ TICKS 6 ALLOT 1 TIME 16 (of 200) ]
[ time 384 ] Run JOB 0 at PRIORITY 0 [ TICKS 5 ALLOT 1 TIME 15 (of 200) ]
[ time 385 ] Run JOB 0 at PRIORITY 0 [ TICKS 4 ALLOT 1 TIME 14 (of 200) ]
[ time 386 ] Run JOB 0 at PRIORITY 0 [ TICKS 3 ALLOT 1 TIME 13 (of 200) ]
[ time 387 ] Run JOB 0 at PRIORITY 0 [ TICKS 2 ALLOT 1 TIME 12 (of 200) ]
[ time 388 ] Run JOB 0 at PRIORITY 0 [ TICKS 1 ALLOT 1 TIME 11 (of 200) ]
[ time 389 ] Run JOB 0 at PRIORITY 0 [ TICKS 0 ALLOT 1 TIME 10 (of 200) ]
[ time 390 ] Run JOB 0 at PRIORITY 0 [ TICKS 9 ALLOT 1 TIME 9 (of 200) ]
[ time 391 ] Run JOB 0 at PRIORITY 0 [ TICKS 8 ALLOT 1 TIME 8 (of 200) ]
[ time 392 ] Run JOB 0 at PRIORITY 0 [ TICKS 7 ALLOT 1 TIME 7 (of 200) ]
[ time 393 ] Run JOB 0 at PRIORITY 0 [ TICKS 6 ALLOT 1 TIME 6 (of 200) ]
[ time 394 ] Run JOB 0 at PRIORITY 0 [ TICKS 5 ALLOT 1 TIME 5 (of 200) ]
[ time 395 ] Run JOB 0 at PRIORITY 0 [ TICKS 4 ALLOT 1 TIME 4 (of 200) ]
[ time 396 ] Run JOB 0 at PRIORITY 0 [ TICKS 3 ALLOT 1 TIME 3 (of 200) ]
[ time 397 ] Run JOB 0 at PRIORITY 0 [ TICKS 2 ALLOT 1 TIME 2 (of 200) ]
[ time 398 ] Run JOB 0 at PRIORITY 0 [ TICKS 1 ALLOT 1 TIME 1 (of 200) ]
[ time 399 ] Run JOB 0 at PRIORITY 0 [ TICKS 0 ALLOT 1 TIME 0 (of 200) ]
[ time 400 ] FINISHED JOB 0

Final statistics:
  Job  0: startTime   0 - response   0 - turnaround 400
  Job  1: startTime 100 - response  10 - turnaround 245
  Job  2: startTime 100 - response  15 - turnaround 250

  Avg  2: startTime n/a - response 8.33 - turnaround 298.33

 Fairness is 0.963


